Workbook
Name A: Naming!#REF!
Name A: Naming!#REF!
Name A: Naming!#REF!
Name Cao_trinh_Vi_tri: Naming!$G$4:$G$16
Name Don_vi_khoi_tao: Naming!$C$4:$C$8
Name Du_an: Naming!$A$4:$A$7
Name Khoi_tich: Naming!$E$4:$E$30
Name Loai_Kieu: Naming!$M$4:$M$33
Name So_thu_tu: Naming!$O$4:$O$5
Name Vai_tro_dam_nhiem: Naming!#REF!
Name Vai_tro_dam_nhiem: Naming!#REF!
Name Vai_tro_dam_nhiem: Naming!#REF!
Name Vai_tro_dam_nhiem: Naming!#REF!
Name Vai_tro_dam_nhiem: Naming!#REF!

Sheet Cover
B4: KẾ HOẠCH CHUYỂN GIAO THÔNG TIN TỔNG THỂ (MIDP)
B7: Phiên bản | C7: Ngày | D7: Người lập | E7: Người phê duyệt | F7: Mô tả
B8: 1.0 | C8: 14/8/2025 | D8: Nguyễn Quốc Anh

Sheet Naming
B1: DANH SÁCH MÃ QUẢN LÝ CỦA DỰ ÁN
A3: Mã | B3: Dự án | C3: Mã | D3: Đơn vị khởi tạo | E3: Mã | F3: Bộ môn | G3: Mã | H3: Tòa nhà | I3: Mã | J3: Nhóm tầng | K3: Mã | L3: Tầng | M3: Mã | N3: Loại/ Kiểu | O3: Mã | P3: Số thứ tự
A4: NO-11 | B4: NHÀ Ở CHUNG CƯ CAO TẦNG TẠI Ô ĐẤT KÝ HIỆU NO-11 | C4: LID | D4: Công ty Cổ phần phát triển đô thị Từ Liêm - LIDECO | E4: FEDE | F4: Tất cả bộ môn | G4: ZZ | H4: Tất cả các tòa | I4: ZZZ | J4: Tất cả nhóm tầng | K4: 01-03 | L4: Tầng 1 - tầng 3 | M4: DR | N4: Bản vẽ 2D | O4: 0001
C5: PAY | D5: Công ty TNHH Paysart Hà Nội | E5: XXXX | F5: không áp dụng bộ môn | G5: XX | H5: Không liên quan tòa nhà | I5: XXX | J5: Không liên quan nhóm tầng | K5: 04-13 | L5: Tầng 4 đến tầng 13 | M5: M3 | N5: Mô hình 3D | O5: 0002
C6: CIC | D6: Công ty CP Công nghệ & Tư vấn CIC | E6: STRU | F6: Kết cấu | G6: CC | H6: Chung cư | I6: POD | J6: Khối đế | K6: 14-28 | L6: Tầng 14 đến tầng 28 | M6: BQ | N6: Bills of Quantity | O6: 0003
C7: FIR | D7: Công ty Cổ phần Firecom | E7: ARCH | F7: Kiến trúc | G7: NN | H7: Ngoài nhà | I7: TOW | J7: Khối tháp | K7: 29-RO | L7: Tầng 29 đến mái | M7: CO | N7: Biên bản họp
E8: MEPF | F8: Cơ điện | I8: BAS | J8: Nhóm tầng hầm | K8: 04-16 | L8: Tầng 4 đến tầng 16 | M8: RI | N8: Yêu cầu thông tin
E9: HVAC | F9: Điều hòa thông gió | K9: 17-RO | L9: Tầng 17 đến mái | M9: RP | N9: Báo cáo
E10: PLUM | F10: Cấp thoát nước | K10: B1 | L10: Tầng hầm 1 | M10: SH | N10: Tiến độ
E11: FIRE | F11: Phòng cháy chữa cháy | K11: B2 | L11: Tầng hầm 2 | M11: PL | N11: Kế hoạch
E12: ELEC | F12: Điện | K12: M01 | L12: Tầng lửng trên tầng 1 | M12: SP | N12: Specification
E13: LAND | F13: Cảnh quan | K13: M02 | L13: Tầng lửng trên tầng 2 | M13: SU | N13: Khảo sát
E14: CIVI | F14: Hạ tầng ngoài nhà | K14: ZZ | L14: Tất cả các tầng | M14: VI | N14: Video
E15: STAR | F15: Kiến trúc & Kết cấu | K15: XX | L15: Không liên quan đến tầng | M15: PI | N15: Hình ảnh
K16: 01 | L16: Tầng 1 | M16: TR | N16: Đào tạo, hướng dẫn
K17: 02 | L17: Tầng 2
A39: Ghi chú: Các mã có thể được mở rộng theo dự án | C39: Ghi chú: Các mã có thể được mở rộng theo dự án | E39: Ghi chú: Các mã có thể được mở rộng theo dự án | G39: Ghi chú: Các mã có thể được mở rộng theo dự án | I39: Ghi chú: Các mã có thể được mở rộng theo dự án | K39: Ghi chú: Các mã có thể được mở rộng theo dự án | M39: Ghi chú: Các mã có thể được mở rộng theo dự án | O39: Ghi chú: Các mã có thể được mở rộng theo dự án

Sheet MIDP
B2: KẾ HOẠCH CHUYỂN GIAO THÔNG TIN TỔNG THỂ (MIDP)
B4: Số hiệu Dự án | C4: =+Naming!A4 -> NO-11
B5: Tiêu đề dự án | C5: =+Naming!B4 -> NHÀ Ở CHUNG CƯ CAO TẦNG TẠI Ô ĐẤT KÝ HIỆU NO-11
B6: Ngày khởi tạo | C6: 17/02/2026
B7: Ngày cập nhật lần cuối | C7: 24/04/2026
B8: Phiên bản | C8: P02
U9: Giai đoạn chuyển giao thông tin
B10: TÀI LIỆU | C10: BỘ MÔN | D10: MÔ TẢ | E10: LOẠI DỮ LIỆU | F10: THỰC HIỆN | G10: ĐỊNH DẠNG TỆP TIN | H10: DỰ ÁN | I10: MÃ TÁC GIẢ | J10: BỘ MÔN | K10: TÒA NHÀ | L10: NHÓM TẦNG | M10: TẦNG | N10: LOẠI/ KIỂU | O10: SỐ THỨ TỰ | P10: VAI TRÒ | Q10: PHÂN LOẠI | R10: TÊN TỆP TIN (tự động) | S10: Số bản vẽ | T10: Tên bản vẽ | U10: Bên khởi tạo | V10: Ngày chuyển giao Dự kiến | W10: Ngày chuyển giao thực tế lần đầu | X10: Ngày chuyển giao thực tế gần nhất | Y10: Phiên bản | Z10: Ngày chuyển giao lần 2 thực tế
B12: 1. Dữ liệu thiết kế
B13: Hồ sơ và dữ liệu thiết kế | D13: Khảo sát địa hình | E13: Báo cáo | G13: PDF | H13: NO-11 | I13: PAY | J13: XXXX | K13: XX | L13: XXX | M13: XX | N13: RP | O13: 0001 | R13: =IF(H13="","_",CONCATENATE(H13,"_",I13,"_",J13,"_",K13,"_",L13,"_",M13,"_",N13,"_",O13)) -> NO-11_PAY_XXXX_XX_XXX_XX_RP_0001 | U13: PAY
D14: Khảo sát địa chất | E14: Báo cáo | G14: PDF | H14: NO-11 | I14: PAY | J14: XXXX | K14: XX | L14: XXX | M14: XX | N14: RP | O14: 0002 | R14: =IF(H14="","_",CONCATENATE(H14,"_",I14,"_",J14,"_",K14,"_",L14,"_",M14,"_",N14,"_",O14)) -> NO-11_PAY_XXXX_XX_XXX_XX_RP_0002 | U14: PAY
D15: Thuyết minh thiết kế | E15: Báo cáo | G15: PDF | H15: NO-11 | I15: PAY | J15: XXXX | K15: XX | L15: XXX | M15: XX | N15: RP | O15: 0003 | R15: =IF(H15="","_",CONCATENATE(H15,"_",I15,"_",J15,"_",K15,"_",L15,"_",M15,"_",N15,"_",O15)) -> NO-11_PAY_XXXX_XX_XXX_XX_RP_0003 | U15: PAY
D16: Bảng tính kết cấu | E16: Tính toán | G16: PDF | H16: NO-11 | I16: PAY | J16: STRU | K16: XX | L16: XXX | M16: XX | N16: RP | O16: 0001 | R16: =IF(H16="","_",CONCATENATE(H16,"_",I16,"_",J16,"_",K16,"_",L16,"_",M16,"_",N16,"_",O16)) -> NO-11_PAY_STRU_XX_XXX_XX_RP_0001 | U16: PAY
D17: Bản vẽ thiết kế thi công | E17: Bản vẽ 2D | G17: PDF | H17: NO-11 | I17: PAY | J17: FEDE | K17: XX | L17: XXX | M17: XX | N17: M2 | O17: 0001 | R17: =IF(H17="","_",CONCATENATE(H17,"_",I17,"_",J17,"_",K17,"_",L17,"_",M17,"_",N17,"_",O17)) -> NO-11_PAY_FEDE_XX_XXX_XX_M2_0001 | U17: PAY
D18: Form BoQ KTKC | E18: Báo cáo | G18: xlsx | H18: NO-11 | I18: PAY | J18: STAR | K18: ZZ | L18: ZZZ | M18: ZZ | N18: BQ | O18: 0001 | R18: =IF(H18="","_",CONCATENATE(H18,"_",I18,"_",J18,"_",K18,"_",L18,"_",M18,"_",N18,"_",O18)) -> NO-11_PAY_STAR_ZZ_ZZZ_ZZ_BQ_0001 | U18: PAY | X18: 21/04/2026
D19: Form BoQ Cơ điện (Không bao gồm PCCC) | E19: Báo cáo | G19: xlsx | H19: NO-11 | I19: PAY | J19: MEPF | K19: ZZ | L19: ZZZ | M19: ZZ | N19: BQ | O19: 0001 | R19: =IF(H19="","_",CONCATENATE(H19,"_",I19,"_",J19,"_",K19,"_",L19,"_",M19,"_",N19,"_",O19)) -> NO-11_PAY_MEPF_ZZ_ZZZ_ZZ_BQ_0001 | U19: PAY | X19: 17/04/2026
D20: Form BoQ PCCC | E20: Báo cáo | G20: xlsx | H20: NO-11 | I20: FIR | J20: FIRE | K20: ZZ | L20: ZZZ | M20: ZZ | N20: BQ | O20: 0001 | R20: =IF(H20="","_",CONCATENATE(H20,"_",I20,"_",J20,"_",K20,"_",L20,"_",M20,"_",N20,"_",O20)) -> NO-11_FIR_FIRE_ZZ_ZZZ_ZZ_BQ_0001 | U20: FIR | X20: 17/04/2026
D21: Chỉ dẫn kỹ thuật của dự án | E21: Báo cáo | G21: PDF | H21: NO-11 | I21: PAY | J21: XXXX | K21: XX | L21: XXX | M21: XX | N21: SP | O21: 0001 | R21: =IF(H21="","_",CONCATENATE(H21,"_",I21,"_",J21,"_",K21,"_",L21,"_",M21,"_",N21,"_",O21)) -> NO-11_PAY_XXXX_XX_XXX_XX_SP_0001 | U21: PAY
B22: 2. Kế hoạch và thủ tục | R22: =IF(H22="","_",CONCATENATE(H22,"_",I22,"_",J22,"_",K22,"_",L22,"_",M22,"_",N22,"_",O22)) -> _
B23: Kế hoạch triển khai BIM - BEP | D23: Kế hoạch triển khai BIM | E23: Tài liệu | G23: PDF | H23: NO-11 | I23: CIC | J23: XXXX | K23: XX | L23: XXX | M23: XX | N23: PL | O23: 0001 | R23: =IF(H23="","_",CONCATENATE(H23,"_",I23,"_",J23,"_",K23,"_",L23,"_",M23,"_",N23,"_",O23)) -> NO-11_CIC_XXXX_XX_XXX_XX_PL_0001 | U23: CIC | V23: 27/01/2026 | X23: 10/03/2026 | Y23: 01
D24: Phụ lục về thông tin phi hình học | E24: Tài liệu | G24: PDF | H24: NO-11 | I24: CIC | J24: XXXX | K24: XX | L24: XXX | M24: XX | N24: PL | O24: 0002 | R24: =IF(H24="","_",CONCATENATE(H24,"_",I24,"_",J24,"_",K24,"_",L24,"_",M24,"_",N24,"_",O24)) -> NO-11_CIC_XXXX_XX_XXX_XX_PL_0002 | U24: CIC | V24: 27/01/2026 | X24: 10/03/2026 | Y24: 01
D25: Phụ lục MIDP | E25: Tài liệu | G25: PDF | H25: NO-11 | I25: CIC | J25: XXXX | K25: XX | L25: XXX | M25: XX | N25: PL | O25: 0003 | R25: =IF(H25="","_",CONCATENATE(H25,"_",I25,"_",J25,"_",K25,"_",L25,"_",M25,"_",N25,"_",O25)) -> NO-11_CIC_XXXX_XX_XXX_XX_PL_0003 | U25: CIC | V25: 27/01/2026 | X25: 13/03/2026 | Y25: 02
B26: Đào tạo | D26: Hướng dẫn sử dụng CDE | E26: Tài liệu | G26: PDF | H26: NO-11 | I26: CIC | J26: XXXX | K26: XX | L26: XXX | M26: XX | N26: TR | O26: 0001 | R26: =IF(H26="","_",CONCATENATE(H26,"_",I26,"_",J26,"_",K26,"_",L26,"_",M26,"_",N26,"_",O26)) -> NO-11_CIC_XXXX_XX_XXX_XX_TR_0001 | U26: CIC
B27: 3. Mô hình | R27: =IF(H27="","_",CONCATENATE(H27,"_",I27,"_",J27,"_",K27,"_",L27,"_",M27,"_",N27,"_",O27)) -> _
B28: Mô hình phần hầm khối chung cư | C28: Kết cấu | D28: Mô hình kết cấu phần hầm | E28: Mô hình 3D | G28: RVT, NWC, IFC | H28: NO-11 | I28: CIC | J28: STRU | K28: CC | L28: BAS | M28: ZZ | N28: M3 | O28: 0001 | R28: =IF(H28="","_",CONCATENATE(H28,"_",I28,"_",J28,"_",K28,"_",L28,"_",M28,"_",N28,"_",O28)) -> NO-11_CIC_STRU_CC_BAS_ZZ_M3_0001 | U28: CIC | V28: 07/02/2026 | W28: 03/03/2026 | X28: 08/04/2026 | Y28: 04
C29: Kiến trúc | D29: Mô hình kiến trúc phần hầm | E29: Mô hình 3D | G29: RVT, NWC, IFC | H29: NO-11 | I29: CIC | J29: ARCH | K29: CC | L29: BAS | M29: ZZ | N29: M3 | O29: 0001 | R29: =IF(H29="","_",CONCATENATE(H29,"_",I29,"_",J29,"_",K29,"_",L29,"_",M29,"_",N29,"_",O29)) -> NO-11_CIC_ARCH_CC_BAS_ZZ_M3_0001 | U29: CIC | V29: 07/02/2026 | W29: 03/03/2026 | X29: 08/04/2026 | Y29: 03
C30: Điều hòa thông gió | D30: Mô hình Điều hòa thông gió phần hầm | E30: Mô hình 3D | G30: RVT, NWC, IFC | H30: NO-11 | I30: CIC | J30: HVAC | K30: CC | L30: BAS | M30: ZZ | N30: M3 | O30: 0001 | R30: =IF(H30="","_",CONCATENATE(H30,"_",I30,"_",J30,"_",K30,"_",L30,"_",M30,"_",N30,"_",O30)) -> NO-11_CIC_HVAC_CC_BAS_ZZ_M3_0001 | U30: CIC | V30: 07/02/2026 | W30: 03/03/2026 | X30: 08/04/2026 | Y30: 03
C31: Cấp thoát nước | D31: Mô hình Cấp thoát nước phần hầm | E31: Mô hình 3D | G31: RVT, NWC, IFC | H31: NO-11 | I31: CIC | J31: PLUM | K31: CC | L31: BAS | M31: ZZ | N31: M3 | O31: 0001 | R31: =IF(H31="","_",CONCATENATE(H31,"_",I31,"_",J31,"_",K31,"_",L31,"_",M31,"_",N31,"_",O31)) -> NO-11_CIC_PLUM_CC_BAS_ZZ_M3_0001 | U31: CIC | V31: 07/02/2026 | W31: 03/03/2026 | X31: 08/04/2026 | Y31: 03
C32: Điện | D32: Mô hình Điện phần hầm | E32: Mô hình 3D | G32: RVT, NWC, IFC | H32: NO-11 | I32: CIC | J32: ELEC | K32: CC | L32: BAS | M32: ZZ | N32: M3 | O32: 0001 | R32: =IF(H32="","_",CONCATENATE(H32,"_",I32,"_",J32,"_",K32,"_",L32,"_",M32,"_",N32,"_",O32)) -> NO-11_CIC_ELEC_CC_BAS_ZZ_M3_0001 | U32: CIC | V32: 07/02/2026 | W32: 03/03/2026 | X32: 08/04/2026 | Y32: 03
C33: Phòng cháy chữa cháy | D33: Mô hình Phòng cháy chữa cháy phần hầm | E33: Mô hình 3D | G33: RVT, NWC, IFC | H33: NO-11 | I33: CIC | J33: FIRE | K33: CC | L33: BAS | M33: ZZ | N33: M3 | O33: 0001 | R33: =IF(H33="","_",CONCATENATE(H33,"_",I33,"_",J33,"_",K33,"_",L33,"_",M33,"_",N33,"_",O33)) -> NO-11_CIC_FIRE_CC_BAS_ZZ_M3_0001 | U33: CIC | V33: 07/02/2026 | W33: 03/03/2026 | X33: 08/04/2026 | Y33: 03
B34: Mô hình khu Podium khối chung cư | C34: Kết cấu | D34: Mô hình kết cấu khu Podium | E34: Mô hình 3D | G34: RVT, NWC, IFC | H34: NO-11 | I34: CIC | J34: STRU | K34: CC | L34: POD | M34: ZZ | N34: M3 | O34: 0001 | R34: =IF(H34="","_",CONCATENATE(H34,"_",I34,"_",J34,"_",K34,"_",L34,"_",M34,"_",N34,"_",O34)) -> NO-11_CIC_STRU_CC_POD_ZZ_M3_0001 | U34: CIC | V34: 13/02/2026 | W34: 06/03/2026 | X34: 08/04/2026 | Y34: 04
C35: Kiến trúc | D35: Mô hình kiến trúc khu Podium | E35: Mô hình 3D | G35: RVT, NWC, IFC | H35: NO-11 | I35: CIC | J35: ARCH | K35: CC | L35: POD | M35: ZZ | N35: M3 | O35: 0001 | R35: =IF(H35="","_",CONCATENATE(H35,"_",I35,"_",J35,"_",K35,"_",L35,"_",M35,"_",N35,"_",O35)) -> NO-11_CIC_ARCH_CC_POD_ZZ_M3_0001 | U35: CIC | V35: 13/02/2026 | W35: 06/03/2026 | X35: 08/04/2026 | Y35: 04
C36: Điều hòa thông gió | D36: Mô hình Điều hòa thông gió khu Podium | E36: Mô hình 3D | G36: RVT, NWC, IFC | H36: NO-11 | I36: CIC | J36: HVAC | K36: CC | L36: POD | M36: ZZ | N36: M3 | O36: 0001 | R36: =IF(H36="","_",CONCATENATE(H36,"_",I36,"_",J36,"_",K36,"_",L36,"_",M36,"_",N36,"_",O36)) -> NO-11_CIC_HVAC_CC_POD_ZZ_M3_0001 | U36: CIC | V36: 13/02/2026 | W36: 06/03/2026 | X36: 08/04/2026 | Y36: 04
C37: Cấp thoát nước | D37: Mô hình Cấp thoát nướckhu Podium | E37: Mô hình 3D | G37: RVT, NWC, IFC | H37: NO-11 | I37: CIC | J37: PLUM | K37: CC | L37: POD | M37: ZZ | N37: M3 | O37: 0001 | R37: =IF(H37="","_",CONCATENATE(H37,"_",I37,"_",J37,"_",K37,"_",L37,"_",M37,"_",N37,"_",O37)) -> NO-11_CIC_PLUM_CC_POD_ZZ_M3_0001 | U37: CIC | V37: 13/02/2026 | W37: 06/03/2026 | X37: 08/04/2026 | Y37: 03
C38: Điện | D38: Mô hình Điện khu Podium | E38: Mô hình 3D | G38: RVT, NWC, IFC | H38: NO-11 | I38: CIC | J38: ELEC | K38: CC | L38: POD | M38: ZZ | N38: M3 | O38: 0001 | R38: =IF(H38="","_",CONCATENATE(H38,"_",I38,"_",J38,"_",K38,"_",L38,"_",M38,"_",N38,"_",O38)) -> NO-11_CIC_ELEC_CC_POD_ZZ_M3_0001 | U38: CIC | V38: 13/02/2026 | W38: 06/03/2026 | X38: 08/04/2026 | Y38: 04
C39: Phòng cháy chữa cháy | D39: Mô hình Phòng cháy chữa cháy khu Podium | E39: Mô hình 3D | G39: RVT, NWC, IFC | H39: NO-11 | I39: CIC | J39: FIRE | K39: CC | L39: POD | M39: ZZ | N39: M3 | O39: 0001 | R39: =IF(H39="","_",CONCATENATE(H39,"_",I39,"_",J39,"_",K39,"_",L39,"_",M39,"_",N39,"_",O39)) -> NO-11_CIC_FIRE_CC_POD_ZZ_M3_0001 | U39: CIC | V39: 13/02/2026 | W39: 06/03/2026 | X39: 08/04/2026 | Y39: 03
B40: Mô hình khu căn hộ khối chung cư | C40: Mô hình kết cấu | D40: Mô hình kết cấu tầng 7 | E40: Mô hình 3D | G40: RVT, NWC, IFC | H40: NO-11 | I40: CIC | J40: STRU | K40: CC | L40: TOW | M40: 07 | N40: M3 | O40: 0001 | R40: =IF(H40="","_",CONCATENATE(H40,"_",I40,"_",J40,"_",K40,"_",L40,"_",M40,"_",N40,"_",O40)) -> NO-11_CIC_STRU_CC_TOW_07_M3_0001 | U40: CIC | V40: 27/02/2026 | W40: 13/03/2026 | X40: 22/04/2026 | Y40: 05
D41: Mô hình kết cấu tầng 8 đến 32 | E41: Mô hình 3D | G41: RVT | H41: NO-11 | I41: CIC | J41: STRU | K41: CC | L41: TOW | M41: 08-32 | N41: M3 | O41: 0001 | R41: =IF(H41="","_",CONCATENATE(H41,"_",I41,"_",J41,"_",K41,"_",L41,"_",M41,"_",N41,"_",O41)) -> NO-11_CIC_STRU_CC_TOW_08-32_M3_0001 | U41: CIC | V41: 27/02/2026 | W41: 13/03/2026 | X41: 22/04/2026 | Y41: 05
D42: Mô hình kết cấu tầng tum, mái | E42: Mô hình 3D | G42: RVT, NWC, IFC | H42: NO-11 | I42: CIC | J42: STRU | K42: CC | L42: TOW | M42: MA | N42: M3 | O42: 0001 | R42: =IF(H42="","_",CONCATENATE(H42,"_",I42,"_",J42,"_",K42,"_",L42,"_",M42,"_",N42,"_",O42)) -> NO-11_CIC_STRU_CC_TOW_MA_M3_0001 | U42: CIC | V42: 27/02/2026 | W42: 13/03/2026 | X42: 15/04/2026 | Y42: 04
C43: Mô hình kiến trúc | D43: Mô hình kiến trúc tầng 7 | E43: Mô hình 3D | G43: RVT, NWC, IFC | H43: NO-11 | I43: CIC | J43: ARCH | K43: CC | L43: TOW | M43: 07 | N43: M3 | O43: 0001 | R43: =IF(H43="","_",CONCATENATE(H43,"_",I43,"_",J43,"_",K43,"_",L43,"_",M43,"_",N43,"_",O43)) -> NO-11_CIC_ARCH_CC_TOW_07_M3_0001 | U43: CIC | V43: 27/02/2026 | W43: 13/03/2026 | X43: 22/04/2026 | Y43: 04
...

Sheet LIST_TT
A1: DANH MỤC BẢN VẼ
A2: STT | B2: SỐ BẢN VẼ | C2: TÊN BẢN VẼ
A3: TỔNG THỂ
A4: 1 | B4: =MIDP!S86 -> 0 | C4: =MIDP!T86 -> 0
A5: =A4+1 -> 2 | B5: =MIDP!#REF! -> #REF! | C5: =MIDP!#REF! -> #REF!
A6: =A5+1 -> 3 | B6: =MIDP!#REF! -> #REF! | C6: =MIDP!#REF! -> #REF!
A7: =A6+1 -> 4 | B7: =MIDP!#REF! -> #REF! | C7: =MIDP!#REF! -> #REF!
A8: =A7+1 -> 5 | B8: =MIDP!#REF! -> #REF! | C8: =MIDP!#REF! -> #REF!
A9: =A8+1 -> 6 | B9: =MIDP!#REF! -> #REF! | C9: =MIDP!#REF! -> #REF!
A10: =A9+1 -> 7 | B10: =MIDP!#REF! -> #REF! | C10: =MIDP!#REF! -> #REF!
A11: =A10+1 -> 8 | B11: =MIDP!#REF! -> #REF! | C11: =MIDP!#REF! -> #REF!
A12: =A11+1 -> 9 | B12: =MIDP!#REF! -> #REF! | C12: =MIDP!#REF! -> #REF!
A13: =A12+1 -> 10 | B13: =MIDP!#REF! -> #REF! | C13: =MIDP!#REF! -> #REF!
A14: =A13+1 -> 11 | B14: =MIDP!#REF! -> #REF! | C14: =MIDP!#REF! -> #REF!
A15: =A14+1 -> 12 | B15: =MIDP!#REF! -> #REF! | C15: =MIDP!#REF! -> #REF!
A16: =A15+1 -> 13 | B16: =MIDP!#REF! -> #REF! | C16: =MIDP!#REF! -> #REF!
... A29: =A28+1 -> 26 | B29: =MIDP!#REF! -> #REF! | C29: =MIDP!#REF! -> #REF!

Sheet LIST_BAS
A1: DANH MỤC BẢN VẼ
A2: STT | B2: SỐ BẢN VẼ | C2: TÊN BẢN VẼ
A3: PHẦN HẦM
A4: 1 | B4: =MIDP!#REF! -> #REF! | C4: =MIDP!#REF! -> #REF!
A5: =A4+1 -> 2 | B5: =MIDP!#REF! -> #REF! | C5: =MIDP!#REF! -> #REF!
A6: =A5+1 -> 3 | B6: =MIDP!#REF! -> #REF! | C6: =MIDP!#REF! -> #REF!
A7: =A6+1 -> 4 | B7: =MIDP!#REF! -> #REF! | C7: =MIDP!#REF! -> #REF!
A8: =A7+1 -> 5 | B8: =MIDP!#REF! -> #REF! | C8: =MIDP!#REF! -> #REF!
A9: =A8+1 -> 6 | B9: =MIDP!#REF! -> #REF! | C9: =MIDP!#REF! -> #REF!
A10: =A9+1 -> 7 | B10: =MIDP!#REF! -> #REF! | C10: =MIDP!#REF! -> #REF!
A11: =A10+1 -> 8 | B11: =MIDP!#REF! -> #REF! | C11: =MIDP!#REF! -> #REF!
A12: =A11+1 -> 9 | B12: =MIDP!#REF! -> #REF! | C12: =MIDP!#REF! -> #REF!
A13: =A12+1 -> 10 | B13: =MIDP!#REF! -> #REF! | C13: =MIDP!#REF! -> #REF!
A14: =A13+1 -> 11 | B14: =MIDP!#REF! -> #REF! | C14: =MIDP!#REF! -> #REF!
A15: =A14+1 -> 12 | B15: =MIDP!#REF! -> #REF! | C15: =MIDP!#REF! -> #REF!
A16: =A15+1 -> 13 | B16: =MIDP!#REF! -> #REF! | C16: =MIDP!#REF! -> #REF!
... A76: =A75+1 -> 73 | B76: =MIDP!#REF! -> #REF! | C76: =MIDP!#REF! -> #REF!

Sheet LIST_TA
A1: DANH MỤC BẢN VẼ
A2: STT | B2: SỐ BẢN VẼ | C2: TÊN BẢN VẼ | E2: STT | F2: SỐ BẢN VẼ | G2: TÊN BẢN VẼ
A3: THÁP A | E3: =A50+1 -> 48 | F3: =MIDP!#REF! -> #REF! | G3: =MIDP!#REF! -> #REF!
A4: 1 | B4: =MIDP!#REF! -> #REF! | C4: =MIDP!#REF! -> #REF! | E4: =E3+1 -> 49 | F4: =MIDP!#REF! -> #REF! | G4: =MIDP!#REF! -> #REF!
A5: =A4+1 -> 2 | B5: =MIDP!#REF! -> #REF! | C5: =MIDP!#REF! -> #REF! | E5: =E4+1 -> 50 | F5: =MIDP!#REF! -> #REF! | G5: =MIDP!#REF! -> #REF!
A6: =A5+1 -> 3 | B6: =MIDP!#REF! -> #REF! | C6: =MIDP!#REF! -> #REF! | E6: =E5+1 -> 51 | F6: =MIDP!#REF! -> #REF! | G6: =MIDP!#REF! -> #REF!
A7: =A6+1 -> 4 | B7: =MIDP!#REF! -> #REF! | C7: =MIDP!#REF! -> #REF! | E7: =E6+1 -> 52 | F7: =MIDP!#REF! -> #REF! | G7: =MIDP!#REF! -> #REF!
A8: =A7+1 -> 5 | B8: =MIDP!#REF! -> #REF! | C8: =MIDP!#REF! -> #REF! | E8: =E7+1 -> 53 | F8: =MIDP!#REF! -> #REF! | G8: =MIDP!#REF! -> #REF!
A9: =A8+1 -> 6 | B9: =MIDP!#REF! -> #REF! | C9: =MIDP!#REF! -> #REF! | E9: =E8+1 -> 54 | F9: =MIDP!#REF! -> #REF! | G9: =MIDP!#REF! -> #REF!
A10: =A9+1 -> 7 | B10: =MIDP!#REF! -> #REF! | C10: =MIDP!#REF! -> #REF! | E10: =E9+1 -> 55 | F10: =MIDP!#REF! -> #REF! | G10: =MIDP!#REF! -> #REF!
A11: =A10+1 -> 8 | B11: =MIDP!#REF! -> #REF! | C11: =MIDP!#REF! -> #REF! | E11: =E10+1 -> 56 | F11: =MIDP!#REF! -> #REF! | G11: =MIDP!#REF! -> #REF!
A12: =A11+1 -> 9 | B12: =MIDP!#REF! -> #REF! | C12: =MIDP!#REF! -> #REF! | E12: =E11+1 -> 57 | F12: =MIDP!#REF! -> #REF! | G12: =MIDP!#REF! -> #REF!
A13: =A12+1 -> 10 | B13: =MIDP!#REF! -> #REF! | C13: =MIDP!#REF! -> #REF! | E13: =E12+1 -> 58 | F13: =MIDP!#REF! -> #REF! | G13: =MIDP!#REF! -> #REF!
A14: =A13+1 -> 11 | B14: =MIDP!#REF! -> #REF! | C14: =MIDP!#REF! -> #REF! | E14: =E13+1 -> 59 | F14: =MIDP!#REF! -> #REF! | G14: =MIDP!#REF! -> #REF!
A15: =A14+1 -> 12 | B15: =MIDP!#REF! -> #REF! | C15: =MIDP!#REF! -> #REF! | E15: =E14+1 -> 60 | F15: =MIDP!#REF! -> #REF! | G15: =MIDP!#REF! -> #REF!
A16: =A15+1 -> 13 | B16: =MIDP!#REF! -> #REF! | C16: =MIDP!#REF! -> #REF! | E16: =E15+1 -> 61 | F16: =MIDP!#REF! -> #REF! | G16: =MIDP!#REF! -> #REF!
... A48: =A47+1 -> 45 | B48: =MIDP!#REF! -> #REF! | C48: =MIDP!#REF! -> #REF! | E48: =E47+1 -> 93 | F48: =MIDP!#REF! -> #REF! | G48: =MIDP!#REF! -> #REF!
A49: =A48+1 -> 46 | B49: =MIDP!#REF! -> #REF! | C49: =MIDP!#REF! -> #REF!
A50: =A49+1 -> 47 | B50: =MIDP!#REF! -> #REF! | C50: =MIDP!#REF! -> #REF!

Sheet LIST_TB1
A1: DANH MỤC BẢN VẼ
A2: STT | B2: SỐ BẢN VẼ | C2: TÊN BẢN VẼ
A3: THÁP B1
A4: 1 | B4: =MIDP!#REF! -> #REF! | C4: =MIDP!#REF! -> #REF!
A5: =A4+1 -> 2 | B5: =MIDP!#REF! -> #REF! | C5: =MIDP!#REF! -> #REF!
A6: =A5+1 -> 3 | B6: =MIDP!#REF! -> #REF! | C6: =MIDP!#REF! -> #REF!
A7: =A6+1 -> 4 | B7: =MIDP!#REF! -> #REF! | C7: =MIDP!#REF! -> #REF!
A8: =A7+1 -> 5 | B8: =MIDP!#REF! -> #REF! | C8: =MIDP!#REF! -> #REF!
A9: =A8+1 -> 6 | B9: =MIDP!#REF! -> #REF! | C9: =MIDP!#REF! -> #REF!
A10: =A9+1 -> 7 | B10: =MIDP!#REF! -> #REF! | C10: =MIDP!#REF! -> #REF!
A11: =A10+1 -> 8 | B11: =MIDP!#REF! -> #REF! | C11: =MIDP!#REF! -> #REF!
A12: =A11+1 -> 9 | B12: =MIDP!#REF! -> #REF! | C12: =MIDP!#REF! -> #REF!
A13: =A12+1 -> 10 | B13: =MIDP!#REF! -> #REF! | C13: =MIDP!#REF! -> #REF!
A14: =A13+1 -> 11 | B14: =MIDP!#REF! -> #REF! | C14: =MIDP!#REF! -> #REF!
A15: =A14+1 -> 12 | B15: =MIDP!#REF! -> #REF! | C15: =MIDP!#REF! -> #REF!
A16: =A15+1 -> 13 | B16: =MIDP!#REF! -> #REF! | C16: =MIDP!#REF! -> #REF!
... A78: =A77+1 -> 75 | B78: =MIDP!#REF! -> #REF! | C78: =MIDP!#REF! -> #REF!

Sheet LIST_TB2
A1: DANH MỤC BẢN VẼ
A2: STT | B2: SỐ BẢN VẼ | C2: TÊN BẢN VẼ
A3: THÁP B2
A4: 1 | B4: =MIDP!#REF! -> #REF! | C4: =MIDP!#REF! -> #REF!
A5: =A4+1 -> 2 | B5: =MIDP!#REF! -> #REF! | C5: =MIDP!#REF! -> #REF!
A6: =A5+1 -> 3 | B6: =MIDP!#REF! -> #REF! | C6: =MIDP!#REF! -> #REF!
A7: =A6+1 -> 4 | B7: =MIDP!#REF! -> #REF! | C7: =MIDP!#REF! -> #REF!
A8: =A7+1 -> 5 | B8: =MIDP!#REF! -> #REF! | C8: =MIDP!#REF! -> #REF!
A9: =A8+1 -> 6 | B9: =MIDP!#REF! -> #REF! | C9: =MIDP!#REF! -> #REF!
A10: =A9+1 -> 7 | B10: =MIDP!#REF! -> #REF! | C10: =MIDP!#REF! -> #REF!
A11: =A10+1 -> 8 | B11: =MIDP!#REF! -> #REF! | C11: =MIDP!#REF! -> #REF!
A12: =A11+1 -> 9 | B12: =MIDP!#REF! -> #REF! | C12: =MIDP!#REF! -> #REF!
A13: =A12+1 -> 10 | B13: =MIDP!#REF! -> #REF! | C13: =MIDP!#REF! -> #REF!
A14: =A13+1 -> 11 | B14: =MIDP!#REF! -> #REF! | C14: =MIDP!#REF! -> #REF!
A15: =A14+1 -> 12 | B15: =MIDP!#REF! -> #REF! | C15: =MIDP!#REF! -> #REF!
A16: =A15+1 -> 13 | B16: =MIDP!#REF! -> #REF! | C16: =MIDP!#REF! -> #REF!
... A78: =A77+1 -> 75 | B78: =MIDP!#REF! -> #REF! | C78: =MIDP!#REF! -> #REF!

Sheet Sheet3
E13: 25075-486NH_CIC_STRU_BAS_ZZ
E14: 25075-486NH_CIC_STRU_TA_01-03
E15: 25075-486NH_CIC_STRU_TA_04-13
E16: 25075-486NH_CIC_STRU_TA_14-28
E17: 25075-486NH_CIC_STRU_TA_29-RO
E18: 25075-486NH_CIC_STRU_B1_01-03
E19: 25075-486NH_CIC_STRU_B1_04-16
E20: 25075-486NH_CIC_STRU_B1_17-RO
E21: 25075-486NH_CIC_STRU_B2_01-03
E22: 25075-486NH_CIC_STRU_B2_04-16
E23: 25075-486NH_CIC_STRU_B2_17-RO
E25: 25075-486NH_CIC_ARCH_BAS_ZZ
... E73: 25075-486NH_CIC_ELEC_B2_17-RO

Sheet Sheet1
A1: BẢNG MÔ HÌNH THÀNH PHẦN CÔNG TRÌNH HẠ TẦNG
A2: Hướng dẫn: Bảng Mô Hình Thành Phần (Model Element Table) là tài liệu các thông tin hình học và phi hình học cần thiết của từng phần tử mô hình được sử dụng trong Thông tin Trao đổi cần thiết. Mức Phát Triển (Level of Development - LOD) xác định sự chi tiết và độ hoàn thiện của hình học của một đối tượng cho một mục đích cụ thể (ví dụ, BIMForum LOD 100, 200, 300, 350, và 400). Mức Thông Tin (Level of Information - LOI) xác định các thuộc tính thông tin nên được bao gồm cho mỗi đối tượng (ví dụ, BIMForum LOD 100, 200, 300, 350, 400 từ Bảng Thuộc Tính Thông Tin). Mức Độ Chính Xác (Level of Accuracy - LOA) xác định tính đáng tin cậy của dữ liệu đồ họa cần thiết để hỗ trợ trao đổi thông tin và việc sử dụng mô hình vận hành. (ví dụ, US IBD LOA 10, 20, 30, 40, 50). Định Dạng Thông Tin (Information Format) xác định định dạng đồ họa và yêu cầu thông tin (ví dụ, 2D, 2D+Thông tin, 3D, 3D+Thông tin). Tác Giả Phần Tử Mô Hình (Author) là viết tắt của tổ chức cung cấp mô hình/thông tin cho một đối tượng được sử dụng trong một trao đổi thông tin. Nhân bản các Cột Thông tin Trao đổi cho mỗi Thông tin Trao đổi.
E3: TÊN TRAO ĐỔI THÔNG TIN | K3: TÊN TRAO ĐỔI THÔNG TIN
A4: THÀNH PHẦN MÔ HÌNH (Aligned with IFC Bridge Model View Definition) | E4: LOD | F4: LOI | G4: LOA | H4: Định dạng | I4: Tác giả | J4: Ghi chú | K4: LOD | L4: LOI | M4: LOA | N4: Định dạng | O4: Tác giả | P4: Ghi chú
A5: A | B5: Khảo sát
A6: A | B6: 1 | C6: Địa chính
A7: A | B7: 1 | C7: A | D7: Ranh giới
A8: A | B8: 1 | C8: B | D8: Điểm tham chiếu
A9: A | B9: 1 | C9: C | D9: Quyền sử dụng
A10: A | B10: 1 | C10: D | D10: Mô tả pháp lý
A11: A | B11: 2 | C11: Xây dựng
A12: A | B12: 2 | C12: A | D12: Bố trí
A13: A | B13: 2 | C13: B | D13: Vị trí bố cục
A14: A | B14: 2 | C14: C | D14: Kiểm soát, điều khiển máy móc
A15: A | B15: 3 | C15: Địa hình
A16: A | B16: 3 | C16: A | D16: Hiện trạng
A17: A | B17: 3 | C17: B | D17: Địa hình
A18: B | B18: Giao thông đường bộ
A19: B | B19: 1 | C19: Phương tiện vận chuyển
A20: B | B20: 1 | C20: A | D20: Cơ sở hạ tầng cho người đi bộ
A21: B | B21: 1 | C21: A | D21: Cơ sở hạ tầng cho xe đạp
A22: B | B22: 2 | C22: Lối vào dự án
A23: B | B23: 2 | C23: A | D23: Lối vào dự án
A24: B | B24: 3 | C24: Biện pháp và thiết kế ở dìa dự án
A25: B | B25: 3 | C25: A | D25: Hệ thống vát và lề đường
A26: B | B26: 3 | C26: B | D26: Đường biên an toàn
A27: B | B27: 3 | C27: B | D27: Lề đường
A28: B | B28: 4 | C28: Hình học
A29: B | B29: 4 | C29: A | D29: Hướng ngang
A30: B | B30: 4 | C30: B | D30: Độ dốc
A31: B | B31: 4 | C31: C | D31: Sự nâng
A32: B | B32: 4 | C32: D | D32: Đường cơ sở khác
A33: B | B33: 5 | C33: Nút giao thông
A34: B | B34: 5 | C34: A | D34: Phân làn giao thông
A35: B | B35: 5 | C35: B | D35: Hợp nhất lưu lượng giao thông
A36: B | B36: 5 | C36: C | D36: Đường dốc
A37: B | B37: 5 | C37: D | D37: Cầu vượt/ Đường hầm
A38: B | B38: 6 | C38: Mặt đường
A39: B | B39: 6 | C39: A | D39: Lớp vật liệu lót dưới bề mặt đường
A40: B | B40: 6 | C40: B | D40: Lớp keo trám
...

Sheet Sheet2
A2: Khảo sát
A4: Cadastral
A6: 1A - Biên giới (Boundaries)
A7: 1B - Địa điểm kiểm soát (Control Monuments)
A8: 1C - Quyền sử dụng đất (Easements)
A9: 1D - Mô tả pháp lý (Legal Description)
A10: Xây dựng
A12: 2A - Bố trí (Layout)
A13: 2B - Địa điểm cục bộ (Localizations)
A14: 2C - Điều khiển máy móc (Machine Control)
A15: Topographic (Địa hình)
A17: 3A - Đặc điểm hiện có (Existing Features)
A18: 3B - Địa hình (Terrain)

Sheet KH TH
B2: Kế hoạch chuyển giao thông tin tổng thể (MIDP)
B4: Số hiệu Dự án | C4: =+Naming!A4 -> NO-11
B5: Tiêu đề dự án | C5: =+Naming!B4 -> NHÀ Ở CHUNG CƯ CAO TẦNG TẠI Ô ĐẤT KÝ HIỆU NO-11
B6: Tác giả | C6: Đinh Nho Cảng
B7: Ngày khởi tạo | C7: =+Cover!C8 -> 14/8/2025
B8: Ngày cập nhật lần cuối | C8: =+Cover!C9 -> 0
B9: Tài liệu tham khảo
P10: Tham khảo tài liệu quy ước đặt tên tệp để biết thông tin | X10: Giai đoạn chuyển giao thông tin #1 | AB10: Giai đoạn chuyển giao thông tin #2
P11: Tên tệp tin | X11: Giai đoạn 1 | Y11: Trình thẩm định | AB11: Giai đoạn 2 | AC11: Trình phê duyệt
B13: BỘ MÔN | C13: MÔ TẢ | D13: Thành phần Mô hình | E13: LOẠI DỮ LIỆU (tự động) | F13: ĐỊNH DẠNG TỆP TIN | G13: Team IICM | I13: TEAM THỰC HIỆN | K13: Tiến độ (chuyển song song Ttra) | P13: DỰ ÁN | Q13: BÊN KHỞI TẠO | R13: KHỐI TÍCH/ HỆ THỐNG | S13: CAO TRÌNH/VỊ TRÍ | T13: LOẠI/ KIỂU | U13: VAI TRÒ/ BỘ MÔN | V13: SỐ THỨ TỰ | W13: TÊN TỆP TIN (tự động) | X13: Bên chủ trì | Y13: Ngày chuyển giao (từ thời điểm ký hợp đông) | Z13: LOD | AA13: LOI | AB13: Bên chủ trì | AC13: Ngày chuyển giao (từ thời điểm có thông báo KQTD) | AD13: LOD | AE13: LOI | AI13: =+'[1]TK_TV-Tổng hợp Chi phí'!$D$6+'[1]TK_TV-Tổng hợp Chi phí'!$D$7 -> 1079947000 | AJ13: =+AI13*0.98 -> 1058348060
M14: Phân bổ theo dự toán
B15: 1. Dữ liệu thiết kế | W15: =IF(P15="","-",CONCATENATE(P15,"-",Q15,"-",R15,"-",S15,"-",T15,"-",U15,"-",V15)) -> - | AJ15: 0.35 | AK15: =+AJ13*AJ15 -> 370421821
B16: Hồ sơ và dữ liệu thiết kế | C16: Khảo sát địa hình | E16: Báo cáo | F16: PDF | I16: KSTK | K16: 28-31/5/2024 ~~~~~ | P16: XVNT | Q16: LDTV | R16: ZZ | S16: XX | T16: RP | U16: G | V16: 0001 | W16: =IF(P16="","-",CONCATENATE(P16,"-",Q16,"-",R16,"-",S16,"-",T16,"-",U16,"-",V16)) -> XVNT-LDTV-ZZ-XX-RP-G-0001 | X16: Nhóm khảo sát | Y16: =31-9 -> 22 | AK16: =+AK15*0.94 -> 3.4819651e+08
C17: Khảo sát địa chất | E17: Báo cáo | F17: PDF | I17: KSTK | P17: XVNT | Q17: LDTV | R17: ZZ | S17: XX | T17: RP | U17: G | V17: 0001 | W17: =IF(P17="","-",CONCATENATE(P17,"-",Q17,"-",R17,"-",S17,"-",T17,"-",U17,"-",V17)) -> XVNT-LDTV-ZZ-XX-RP-G-0001 | X17: Nhóm khảo sát
C18: Thuyết minh thiết kế | E18: Báo cáo | F18: PDF | I18: KSTK | P18: XVNT | Q18: LDTV | R18: ZZ | S18: XX | T18: RP | U18: Z | V18: 0001 | W18: =IF(P18="","-",CONCATENATE(P18,"-",Q18,"-",R18,"-",S18,"-",T18,"-",U18,"-",V18)) -> XVNT-LDTV-ZZ-XX-RP-Z-0001 | X18: Nhóm thiết kế
C19: Bảng tính kết cấu | E19: Tính toán | F19: PDF | I19: KSTK | P19: XVNT | Q19: LDTV | R19: ZZ | S19: XX | T19: RP | U19: S | V19: 0001 | W19: =IF(P19="","-",CONCATENATE(P19,"-",Q19,"-",R19,"-",S19,"-",T19,"-",U19,"-",V19)) -> XVNT-LDTV-ZZ-XX-RP-S-0001 | X19: Nhóm thiết kế
C20: Bản vẽ thiết kế thi công | E20: Bản vẽ 2D | F20: PDF | I20: KSTK | K20: 31~xx/5/2024 ~~~~~ | P20: XVNT | Q20: LDTV | R20: ZZ | S20: XX | T20: M2 | U20: Z | V20: 0001 | W20: =IF(P20="","-",CONCATENATE(P20,"-",Q20,"-",R20,"-",S20,"-",T20,"-",U20,"-",V20)) -> XVNT-LDTV-ZZ-XX-M2-Z-0001 | X20: Nhóm thiết kế | Y20: 22~xx/6/2024
C21: Chỉ dẫn kỹ thuật của dự án | E21: Báo cáo | F21: PDF | I21: KSTK | P21: XVNT | Q21: LDTV | R21: ZZ | S21: XX | T21: RP | U21: Z | V21: 0001 | W21: =IF(P21="","-",CONCATENATE(P21,"-",Q21,"-",R21,"-",S21,"-",T21,"-",U21,"-",V21)) -> XVNT-LDTV-ZZ-XX-RP-Z-0001 | X21: Nhóm thiết kế
B22: 2. Kế hoạch và thủ tục | H22: =+M22 -> 25929527 | M22: =+AJ13*AJ15*AJ22/100 -> 25929527 | AJ22: 7
B23: Kế hoạch triển khai BIM - BEP | C23: Kế hoạch triển khai BIM chi tiết | E23: Tài liệu | F23: PDF | G23: 1 | K23: 45453 | P23: XVNT | Q23: IICM | R23: ZZ | S23: XX | T23: MP | U23: W | V23: 0001 | W23: =IF(P23="","-",CONCATENATE(P23,"-",Q23,"-",R23,"-",S23,"-",T23,"-",U23,"-",V23)) -> XVNT-IICM-ZZ-XX-MP-W-0001 | X23: Nhóm BIM | Y23: 30
C24: Các QT và phụ lục | E24: Tài liệu | F24: PDF | G24: 1 | K24: =+K23 -> 45453 | P24: XVNT | Q24: IICM | R24: ZZ | S24: XX | T24: MP | U24: W | V24: 0002 | W24: =IF(P24="","-",CONCATENATE(P24,"-",Q24,"-",R24,"-",S24,"-",T24,"-",U24,"-",V24)) -> XVNT-IICM-ZZ-XX-MP-W-0002 | X24: Nhóm BIM | Y24: 30
B25: CDE, Tiêu chuẩn và thủ tục | C25: Quy định về CED | E25: Tài liệu | F25: PDF | G25: 1 | K25: =+K24 -> 45453 | P25: XVNT | Q25: IICM | R25: ZZ | S25: XX | T25: MP | U25: W | V25: 0003 | W25: =IF(P25="","-",CONCATENATE(P25,"-",Q25,"-",R25,"-",S25,"-",T25,"-",U25,"-",V25)) -> XVNT-IICM-ZZ-XX-MP-W-0003 | X25: Nhóm BIM | Y25: 30
C26: Hướng dẫn sử dụng CDE | E26: Tài liệu | F26: PDF | G26: 1 | K26: =+K25 -> 45453 | P26: XVNT | Q26: IICM | R26: ZZ | S26: XX | T26: MP | U26: W | V26: 0004 | W26: =IF(P26="","-",CONCATENATE(P26,"-",Q26,"-",R26,"-",S26,"-",T26,"-",U26,"-",V26)) -> XVNT-IICM-ZZ-XX-MP-W-0004 | X26: Nhóm BIM | Y26: 30
C27: Tiêu chuẩn và thủ tục mô hình | E27: Tài liệu | F27: PDF | G27: 1 | K27: =+K26 -> 45453 | P27: XVNT | Q27: IICM | R27: ZZ | S27: XX | T27: MP | U27: W | V27: 0005 | W27: =IF(P27="","-",CONCATENATE(P27,"-",Q27,"-",R27,"-",S27,"-",T27,"-",U27,"-",V27)) -> XVNT-IICM-ZZ-XX-MP-W-0005 | X27: Nhóm BIM | Y27: 30
B28: 3. Mô hình | L28: =+L29+L55 -> 1.8521091e+08 | M28: =+AJ13*AJ15*AJ28/100 -> 1.8521091e+08 | AG28: =+L28/AJ13% -> 17.5 | AJ28: 50
J29: =+L29 -> 1.8521091e+08 | L29: =+M28-M55 -> 1.8521091e+08
B30: Mô hình hiện trạng | C30: Địa hình | D30: Bề mặt hiện trạng | E30: Mô hình 3D | F30: NWD | I30: 100 | K30: 45453 | P30: XVNT | Q30: IICM | R30: ZZ | S30: XX | T30: M3 | U30: G1 | V30: 0001 | W30: =IF(P30="","-",CONCATENATE(P30,"-",Q30,"-",R30,"-",S30,"-",T30,"-",U30,"-",V30)) -> XVNT-IICM-ZZ-XX-M3-G1-0001 | X30: Nhóm BIM | Y30: 40 | Z30: 200 | AA30: 200 | AB30: Nhóm BIM | AC30: 30 | AD30: 200 | AE30: 200
C31: Hạ tầng kỹ thuật | D31: Cống, ga các loại | E31: Mô hình 3D | F31: NWD | I31: 100 | K31: 45461 | P31: XVNT | Q31: IICM | R31: ZZ | S31: XX | T31: M3 | U31: G1 | V31: 0001 | W31: =IF(P31="","-",CONCATENATE(P31,"-",Q31,"-",R31,"-",S31,"-",T31,"-",U31,"-",V31)) -> XVNT-IICM-ZZ-XX-M3-G1-0001 | X31: Nhóm BIM | Z31: 200 | AA31: 200 | AB31: Nhóm BIM | AC31: 30 | AD31: 200 | AE31: 200
C32: Địa vật | D32: Trụ đèn, nhà cửa,… | E32: Mô hình 3D | F32: NWD | I32: 100 | K32: 45461 | P32: XVNT | Q32: IICM | R32: ZZ | S32: XX | T32: M3 | U32: G1 | V32: 0001 | W32: =IF(P32="","-",CONCATENATE(P32,"-",Q32,"-",R32,"-",S32,"-",T32,"-",U32,"-",V32)) -> XVNT-IICM-ZZ-XX-M3-G1-0001 | X32: Nhóm BIM | Z32: 200 | AA32: 200 | AB32: Nhóm BIM | AC32: 30 | AD32: 200 | AE32: 200
B33: Mô hình tổng thể | C33: Mô hình phối hợp | D33: Mô hình tổng hợp các bộ môn | E33: Mô hình 3D | F33: NWD | I33: 100 | K33: 45459 | P33: XVNT | Q33: IICM | R33: ZZ | S33: XX | T33: CM | U33: Z | V33: 0001 | W33: =IF(P33="","-",CONCATENATE(P33,"-",Q33,"-",R33,"-",S33,"-",T33,"-",U33,"-",V33)) -> XVNT-IICM-ZZ-XX-CM-Z-0001 | X33: Nhóm BIM | Y33: 40 | Z33: 300 | AB33: Nhóm BIM | AC33: 30 | AD33: 300
B34: Phần tuyến | C34: Mô hình tuyến chính, vỉa hè… | D34: Mô hình tuyến | E34: Mô hình 3D | F34: IFC | I34: 100 | K34: 45453 | P34: XVNT | Q34: IICM | R34: DTC | S34: XX | T34: M3 | U34: C | V34: 0001 | W34: =IF(P34="","-",CONCATENATE(P34,"-",Q34,"-",R34,"-",S34,"-",T34,"-",U34,"-",V34)) -> XVNT-IICM-DTC-XX-M3-C-0001 | X34: Nhóm BIM | Y34: 40 | Z34: 350 | AA34: 350 | AB34: Nhóm BIM | AC34: 30 | AD34: 400 | AE34: 350
D35: Mô hình vỉa hè | E35: Mô hình 3D | F35: IFC | I35: 100 | K35: 45453 | P35: XVNT | Q35: IICM | R35: DTC | S35: XX | T35: M3 | U35: C | V35: 0001 | W35: =IF(P35="","-",CONCATENATE(P35,"-",Q35,"-",R35,"-",S35,"-",T35,"-",U35,"-",V35)) -> XVNT-IICM-DTC-XX-M3-C-0001 | X35: Nhóm BIM | Y35: 40 | Z35: 350 | AA35: 350 | AB35: Nhóm BIM | AC35: 30 | AD35: 350 | AE35: 350
D36: Mô hình nền | E36: Mô hình 3D | F36: IFC | I36: 100 | K36: 45453 | P36: XVNT | Q36: IICM | R36: DTC | S36: XX | T36: M3 | U36: C | V36: 0001 | W36: =IF(P36="","-",CONCATENATE(P36,"-",Q36,"-",R36,"-",S36,"-",T36,"-",U36,"-",V36)) -> XVNT-IICM-DTC-XX-M3-C-0001 | X36: Nhóm BIM | Y36: 40 | Z36: 350 | AA36: 350 | AB36: Nhóm BIM | AC36: 30 | AD36: 400 | AE36: 350
D37: Mô hình XLĐY | E37: Mô hình 3D | F37: IFC | I37: 100 | K37: 45453 | P37: XVNT | Q37: IICM | R37: DTC | S37: XX | T37: M3 | U37: C | V37: 0001 | W37: =IF(P37="","-",CONCATENATE(P37,"-",Q37,"-",R37,"-",S37,"-",T37,"-",U37,"-",V37)) -> XVNT-IICM-DTC-XX-M3-C-0001 | X37: Nhóm BIM | Y37: 40 | Z37: 350 | AA37: 350 | AB37: Nhóm BIM | AC37: 30 | AD37: 350 | AE37: 350
B38: Nút giao | C38: Nút giao đầu tuyến | D38: Mô hình nút giao | E38: Mô hình 3D | F38: IFC | I38: 100 | K38: 45453 | P38: XVNT | Q38: IICM | R38: NG1 | S38: XX | T38: M3 | U38: C | V38: 0001 | W38: =IF(P38="","-",CONCATENATE(P38,"-",Q38,"-",R38,"-",S38,"-",T38,"-",U38,"-",V38)) -> XVNT-IICM-NG1-XX-M3-C-0001 | X38: Nhóm BIM | Y38: 40 | Z38: 400 | AA38: 350 | AB38: Nhóm BIM | AC38: 30 | AD38: 400 | AE38: 350
C39: Nút giao cuối tuyến | D39: Mô hình nút giao | E39: Mô hình 3D | F39: IFC | I39: 100 | K39: 45453 | P39: XVNT | Q39: IICM | R39: NG2 | S39: XX | T39: M3 | U39: C | V39: 0001 | W39: =IF(P39="","-",CONCATENATE(P39,"-",Q39,"-",R39,"-",S39,"-",T39,"-",U39,"-",V39)) -> XVNT-IICM-NG2-XX-M3-C-0001 | X39: Nhóm BIM | Y39: 40 | Z39: 400 | AA39: 350 | AB39: Nhóm BIM | AC39: 30 | AD39: 400 | AE39: 350
C40: Nút giao đường vành đai phía Đông | D40: Mô hình nút giao | E40: Mô hình 3D | F40: IFC | I40: 100 | K40: 45453 | P40: XVNT | Q40: IICM | R40: NG3 | S40: XX | T40: M3 | U40: C | V40: 0001 | W40: =IF(P40="","-",CONCATENATE(P40,"-",Q40,"-",R40,"-",S40,"-",T40,"-",U40,"-",V40)) -> XVNT-IICM-NG3-XX-M3-C-0001 | X40: Nhóm BIM | Y40: 40 | Z40: 400 | AA40: 350 | AB40: Nhóm BIM | AC40: 30 | AD40: 400 | AE40: 350
D41: Mô hình các nhánh | E41: Mô hình 3D | F41: IFC | I41: 100 | K41: 45453 | P41: XVNT | Q41: IICM | R41: NG3 | S41: XX | T41: M3 | U41: C | V41: 0001 | W41: =IF(P41="","-",CONCATENATE(P41,"-",Q41,"-",R41,"-",S41,"-",T41,"-",U41,"-",V41)) -> XVNT-IICM-NG3-XX-M3-C-0001 | X41: Nhóm BIM | Y41: 40 | Z41: 400 | AA41: 350 | AB41: Nhóm BIM | AC41: 30 | AD41: 400 | AE41: 350
B42: Đường nhánh | C42: Đường nhánh và đường giao | D42: Mô hình các đường giao và đường nhánh | E42: Mô hình 3D | F42: IFC | I42: 100 | K42: 45458 | P42: XVNT | Q42: IICM | R42: ZZ | S42: XX | T42: M3 | U42: C | V42: 0001 | W42: =IF(P42="","-",CONCATENATE(P42,"-",Q42,"-",R42,"-",S42,"-",T42,"-",U42,"-",V42)) -> XVNT-IICM-ZZ-XX-M3-C-0001 | X42: Nhóm BIM | Y42: 40 | Z42: 300 | AA42: 300 | AB42: Nhóm BIM | AC42: 30 | AD42: 300 | AE42: 300
B43: Hệ thống hạ tầng kỹ thuật | C43: Hệ thống thoát nước | D43: Mô hình cống ngang nhỏ | E43: Mô hình 3D | F43: IFC | I43: 100 | K43: =+K42 -> 45458 | P43: XVNT | Q43: IICM | R43: CNN | S43: XX | T43: M3 | U43: D | V43: 0001 | W43: =IF(P43="","-",CONCATENATE(P43,"-",Q43,"-",R43,"-",S43,"-",T43,"-",U43,"-",V43)) -> XVNT-IICM-CNN-XX-M3-D-0001 | X43: Nhóm BIM | Y43: 40 | Z43: 300 | AA43: 300 | AB43: Nhóm BIM | AC43: 30 | AD43: 300 | AE43: 300
...

Sheet MIDP 
B2: Kế hoạch chuyển giao thông tin tổng thể (MIDP)
B4: Số hiệu Dự án | C4: =+Naming!A4 -> NO-11
B5: Tiêu đề dự án | C5: =+Naming!B4 -> NHÀ Ở CHUNG CƯ CAO TẦNG TẠI Ô ĐẤT KÝ HIỆU NO-11
B6: Tác giả | C6: Trần Hữu Hải
B7: Ngày khởi tạo | C7: 14/08/2025
B8: Ngày cập nhật lần cuối | C8: 14/08/2025
B9: Tài liệu tham khảo
G10: Tham khảo tài liệu quy ước đặt tên tệp để biết thông tin | O10: Giai đoạn chuyển giao thông tin #1 | S10: Giai đoạn chuyển giao thông tin #2
G11: Tên tệp tin | O11: Giai đoạn 1 | P11: Trình thẩm định | S11: Giai đoạn 2 | T11: Trình phê duyệt
B13: BỘ MÔN | C13: MÔ TẢ | D13: Thành phần Mô hình | E13: LOẠI DỮ LIỆU (tự động) | F13: ĐỊNH DẠNG TỆP TIN | G13: DỰ ÁN | H13: BÊN KHỞI TẠO | I13: KHỐI TÍCH/ HỆ THỐNG | J13: CAO TRÌNH/VỊ TRÍ | K13: LOẠI/ KIỂU | L13: VAI TRÒ/ BỘ MÔN | M13: SỐ THỨ TỰ | N13: TÊN TỆP TIN (tự động) | O13: Bên chủ trì | P13: Ngày chuyển giao (từ thời điểm ký hợp đông) | Q13: LOD | R13: LOI | S13: Bên chủ trì | T13: Ngày chuyển giao (từ thời điểm có thông báo KQTD) | U13: LOD | V13: LOI
B15: 1. Dữ liệu thiết kế | N15: =IF(G15="","-",CONCATENATE(G15,"-",H15,"-",I15,"-",J15,"-",K15,"-",L15,"-",M15)) -> -
B16: Hồ sơ và dữ liệu thiết kế | C16: Khảo sát địa hình | E16: Báo cáo | F16: PDF | G16: XVNT | H16: LDTV | I16: ZZ | J16: XX | K16: RP | L16: G | M16: 0001 | N16: =IF(G16="","-",CONCATENATE(G16,"-",H16,"-",I16,"-",J16,"-",K16,"-",L16,"-",M16)) -> XVNT-LDTV-ZZ-XX-RP-G-0001 | O16: Nhóm khảo sát | P16: 1
C17: Khảo sát địa chất | E17: Báo cáo | F17: PDF | G17: XVNT | H17: LDTV | I17: ZZ | J17: XX | K17: RP | L17: G | M17: 0001 | N17: =IF(G17="","-",CONCATENATE(G17,"-",H17,"-",I17,"-",J17,"-",K17,"-",L17,"-",M17)) -> XVNT-LDTV-ZZ-XX-RP-G-0001 | O17: Nhóm khảo sát | P17: 1
C18: Thuyết minh thiết kế | E18: Báo cáo | F18: PDF | G18: XVNT | H18: LDTV | I18: ZZ | J18: XX | K18: RP | L18: Z | M18: 0001 | N18: =IF(G18="","-",CONCATENATE(G18,"-",H18,"-",I18,"-",J18,"-",K18,"-",L18,"-",M18)) -> XVNT-LDTV-ZZ-XX-RP-Z-0001 | O18: Nhóm thiết kế | P18: 1
C19: Bảng tính kết cấu | E19: Tính toán | F19: PDF | G19: XVNT | H19: LDTV | I19: ZZ | J19: XX | K19: RP | L19: S | M19: 0001 | N19: =IF(G19="","-",CONCATENATE(G19,"-",H19,"-",I19,"-",J19,"-",K19,"-",L19,"-",M19)) -> XVNT-LDTV-ZZ-XX-RP-S-0001 | O19: Nhóm thiết kế | P19: 1
C20: Bản vẽ thiết kế thi công | E20: Bản vẽ 2D | F20: PDF | G20: XVNT | H20: LDTV | I20: ZZ | J20: XX | K20: M2 | L20: Z | M20: 0001 | N20: =IF(G20="","-",CONCATENATE(G20,"-",H20,"-",I20,"-",J20,"-",K20,"-",L20,"-",M20)) -> XVNT-LDTV-ZZ-XX-M2-Z-0001 | O20: Nhóm thiết kế | P20: 1
C21: Chỉ dẫn kỹ thuật của dự án | E21: Báo cáo | F21: PDF | G21: XVNT | H21: LDTV | I21: ZZ | J21: XX | K21: RP | L21: Z | M21: 0001 | N21: =IF(G21="","-",CONCATENATE(G21,"-",H21,"-",I21,"-",J21,"-",K21,"-",L21,"-",M21)) -> XVNT-LDTV-ZZ-XX-RP-Z-0001 | O21: Nhóm thiết kế | P21: 1
B22: 2. Kế hoạch và thủ tục
B23: Kế hoạch triển khai BIM - BEP | C23: Kế hoạch triển khai BIM chi tiết | E23: Tài liệu | F23: PDF | G23: XVNT | H23: IICM | I23: ZZ | J23: XX | K23: MP | L23: W | M23: 0001 | N23: =IF(G23="","-",CONCATENATE(G23,"-",H23,"-",I23,"-",J23,"-",K23,"-",L23,"-",M23)) -> XVNT-IICM-ZZ-XX-MP-W-0001 | O23: Nhóm BIM | P23: 2
C24: Các QT và phụ lục | E24: Tài liệu | F24: PDF | G24: XVNT | H24: IICM | I24: ZZ | J24: XX | K24: MP | L24: W | M24: 0001 | N24: =IF(G24="","-",CONCATENATE(G24,"-",H24,"-",I24,"-",J24,"-",K24,"-",L24,"-",M24)) -> XVNT-IICM-ZZ-XX-MP-W-0001 | O24: Nhóm BIM | P24: 2
B25: CDE, Tiêu chuẩn và thủ tục | C25: Quy định về CDE | E25: Tài liệu | F25: PDF | G25: XVNT | H25: IICM | I25: ZZ | J25: XX | K25: MP | L25: W | M25: 0001 | N25: =IF(G25="","-",CONCATENATE(G25,"-",H25,"-",I25,"-",J25,"-",K25,"-",L25,"-",M25)) -> XVNT-IICM-ZZ-XX-MP-W-0001 | O25: Nhóm BIM | P25: 5
C26: Hướng dẫn sử dụng CDE | E26: Tài liệu | F26: PDF | G26: XVNT | H26: IICM | I26: ZZ | J26: XX | K26: MP | L26: W | M26: 0001 | N26: =IF(G26="","-",CONCATENATE(G26,"-",H26,"-",I26,"-",J26,"-",K26,"-",L26,"-",M26)) -> XVNT-IICM-ZZ-XX-MP-W-0001 | O26: Nhóm BIM | P26: 5
C27: Tiêu chuẩn và thủ tục mô hình | E27: Tài liệu | F27: PDF | G27: XVNT | H27: IICM | I27: ZZ | J27: XX | K27: MP | L27: W | M27: 0005 | N27: =IF(G27="","-",CONCATENATE(G27,"-",H27,"-",I27,"-",J27,"-",K27,"-",L27,"-",M27)) -> XVNT-IICM-ZZ-XX-MP-W-0005 | O27: Nhóm BIM | P27: 30
B28: 3. Mô hình
B29: Mô hình hiện trạng | C29: Địa hình | D29: Bề mặt hiện trạng | E29: Mô hình 3D | F29: NWD | G29: XVNT | H29: IICM | I29: ZZ | J29: XX | K29: M3 | L29: G1 | M29: 0001 | N29: =IF(G29="","-",CONCATENATE(G29,"-",H29,"-",I29,"-",J29,"-",K29,"-",L29,"-",M29)) -> XVNT-IICM-ZZ-XX-M3-G1-0001 | O29: Nhóm BIM | P29: 40 | Q29: 200 | R29: 200 | S29: Nhóm BIM | T29: 30 | U29: 200 | V29: 200
C30: Hạ tầng kỹ thuật | D30: Cống, ga các loại | E30: Mô hình 3D | F30: NWD | G30: XVNT | H30: IICM | I30: ZZ | J30: XX | K30: M3 | L30: G1 | M30: 0001 | N30: =IF(G30="","-",CONCATENATE(G30,"-",H30,"-",I30,"-",J30,"-",K30,"-",L30,"-",M30)) -> XVNT-IICM-ZZ-XX-M3-G1-0001 | O30: Nhóm BIM | Q30: 200 | R30: 200 | S30: Nhóm BIM | T30: 30 | U30: 200 | V30: 200
C31: Địa vật | D31: Trụ đèn, nhà cửa,… | E31: Mô hình 3D | F31: NWD | G31: XVNT | H31: IICM | I31: ZZ | J31: XX | K31: M3 | L31: G1 | M31: 0001 | N31: =IF(G31="","-",CONCATENATE(G31,"-",H31,"-",I31,"-",J31,"-",K31,"-",L31,"-",M31)) -> XVNT-IICM-ZZ-XX-M3-G1-0001 | O31: Nhóm BIM | Q31: 200 | R31: 200 | S31: Nhóm BIM | T31: 30 | U31: 200 | V31: 200
B32: Mô hình tổng thể | C32: Mô hình phối hợp | D32: Mô hình tổng hợp các bộ môn | E32: Mô hình 3D | F32: NWD | G32: XVNT | H32: IICM | I32: ZZ | J32: XX | K32: CM | L32: Z | M32: 0001 | N32: =IF(G32="","-",CONCATENATE(G32,"-",H32,"-",I32,"-",J32,"-",K32,"-",L32,"-",M32)) -> XVNT-IICM-ZZ-XX-CM-Z-0001 | O32: Nhóm BIM | P32: 40 | Q32: 300 | S32: Nhóm BIM | T32: 30 | U32: 300
B33: Phần tuyến | C33: Mô hình tuyến chính, vỉa hè… | D33: Mô hình tuyến | E33: Mô hình 3D | F33: IFC | G33: XVNT | H33: IICM | I33: DTC | J33: XX | K33: M3 | L33: C | M33: 0001 | N33: =IF(G33="","-",CONCATENATE(G33,"-",H33,"-",I33,"-",J33,"-",K33,"-",L33,"-",M33)) -> XVNT-IICM-DTC-XX-M3-C-0001 | O33: Nhóm BIM | P33: 40 | Q33: 350 | R33: 350 | S33: Nhóm BIM | T33: 30 | U33: 400 | V33: 350
D34: Mô hình vỉa hè | E34: Mô hình 3D | F34: IFC | G34: XVNT | H34: IICM | I34: DTC | J34: XX | K34: M3 | L34: C | M34: 0001 | N34: =IF(G34="","-",CONCATENATE(G34,"-",H34,"-",I34,"-",J34,"-",K34,"-",L34,"-",M34)) -> XVNT-IICM-DTC-XX-M3-C-0001 | O34: Nhóm BIM | P34: 40 | Q34: 350 | R34: 350 | S34: Nhóm BIM | T34: 30 | U34: 350 | V34: 350
D35: Mô hình nền | E35: Mô hình 3D | F35: IFC | G35: XVNT | H35: IICM | I35: DTC | J35: XX | K35: M3 | L35: C | M35: 0001 | N35: =IF(G35="","-",CONCATENATE(G35,"-",H35,"-",I35,"-",J35,"-",K35,"-",L35,"-",M35)) -> XVNT-IICM-DTC-XX-M3-C-0001 | O35: Nhóm BIM | P35: 40 | Q35: 350 | R35: 350 | S35: Nhóm BIM | T35: 30 | U35: 400 | V35: 350
D36: Mô hình XLĐY | E36: Mô hình 3D | F36: IFC | G36: XVNT | H36: IICM | I36: DTC | J36: XX | K36: M3 | L36: C | M36: 0001 | N36: =IF(G36="","-",CONCATENATE(G36,"-",H36,"-",I36,"-",J36,"-",K36,"-",L36,"-",M36)) -> XVNT-IICM-DTC-XX-M3-C-0001 | O36: Nhóm BIM | P36: 40 | Q36: 350 | R36: 350 | S36: Nhóm BIM | T36: 30 | U36: 350 | V36: 350
B37: Nút giao | C37: Nút giao đầu tuyến | D37: Mô hình nút giao | E37: Mô hình 3D | F37: IFC | G37: XVNT | H37: IICM | I37: NG1 | J37: XX | K37: M3 | L37: C | M37: 0001 | N37: =IF(G37="","-",CONCATENATE(G37,"-",H37,"-",I37,"-",J37,"-",K37,"-",L37,"-",M37)) -> XVNT-IICM-NG1-XX-M3-C-0001 | O37: Nhóm BIM | P37: 40 | Q37: 400 | R37: 350 | S37: Nhóm BIM | T37: 30 | U37: 400 | V37: 350
C38: Nút giao cuối tuyến | D38: Mô hình nút giao | E38: Mô hình 3D | F38: IFC | G38: XVNT | H38: IICM | I38: NG2 | J38: XX | K38: M3 | L38: C | M38: 0001 | N38: =IF(G38="","-",CONCATENATE(G38,"-",H38,"-",I38,"-",J38,"-",K38,"-",L38,"-",M38)) -> XVNT-IICM-NG2-XX-M3-C-0001 | O38: Nhóm BIM | P38: 40 | Q38: 400 | R38: 350 | S38: Nhóm BIM | T38: 30 | U38: 400 | V38: 350
C39: Nút giao đường vành đai phía Đông | D39: Mô hình nút giao | E39: Mô hình 3D | F39: IFC | G39: XVNT | H39: IICM | I39: NG3 | J39: XX | K39: M3 | L39: C | M39: 0001 | N39: =IF(G39="","-",CONCATENATE(G39,"-",H39,"-",I39,"-",J39,"-",K39,"-",L39,"-",M39)) -> XVNT-IICM-NG3-XX-M3-C-0001 | O39: Nhóm BIM | P39: 40 | Q39: 400 | R39: 350 | S39: Nhóm BIM | T39: 30 | U39: 400 | V39: 350
D40: Mô hình các nhánh | E40: Mô hình 3D | F40: IFC | G40: XVNT | H40: IICM | I40: NG3 | J40: XX | K40: M3 | L40: C | M40: 0001 | N40: =IF(G40="","-",CONCATENATE(G40,"-",H40,"-",I40,"-",J40,"-",K40,"-",L40,"-",M40)) -> XVNT-IICM-NG3-XX-M3-C-0001 | O40: Nhóm BIM | P40: 40 | Q40: 400 | R40: 350 | S40: Nhóm BIM | T40: 30 | U40: 400 | V40: 350
B41: Đường nhánh | C41: Đường nhánh và đường giao | D41: Mô hình các đường giao và đường nhánh | E41: Mô hình 3D | F41: IFC | G41: XVNT | H41: IICM | I41: ZZ | J41: XX | K41: M3 | L41: C | M41: 0001 | N41: =IF(G41="","-",CONCATENATE(G41,"-",H41,"-",I41,"-",J41,"-",K41,"-",L41,"-",M41)) -> XVNT-IICM-ZZ-XX-M3-C-0001 | O41: Nhóm BIM | P41: 40 | Q41: 300 | R41: 300 | S41: Nhóm BIM | T41: 30 | U41: 300 | V41: 300
B42: Hệ thống hạ tầng kỹ thuật | C42: Hệ thống thoát nước | D42: Mô hình cống ngang nhỏ | E42: Mô hình 3D | F42: IFC | G42: XVNT | H42: IICM | I42: CNN | J42: XX | K42: M3 | L42: D | M42: 0001 | N42: =IF(G42="","-",CONCATENATE(G42,"-",H42,"-",I42,"-",J42,"-",K42,"-",L42,"-",M42)) -> XVNT-IICM-CNN-XX-M3-D-0001 | O42: Nhóm BIM | P42: 40 | Q42: 300 | R42: 300 | S42: Nhóm BIM | T42: 30 | U42: 300 | V42: 300
D43: Mô hình cống hộp lớn | E43: Mô hình 3D | F43: IFC | G43: XVNT | H43: IICM | I43: CHL | J43: XX | K43: M3 | L43: D | M43: 0001 | N43: =IF(G43="","-",CONCATENATE(G43,"-",H43,"-",I43,"-",J43,"-",K43,"-",L43,"-",M43)) -> XVNT-IICM-CHL-XX-M3-D-0001 | O43: Nhóm BIM | P43: 40 | Q43: 300 | R43: 300 | S43: Nhóm BIM | T43: 30 | U43: 350 | V43: 350
D44: Mô hình hệ thống thoát nước dọc | E44: Mô hình 3D | F44: IFC | G44: XVNT | H44: IICM | I44: TNM | J44: XX | K44: M3 | L44: D | M44: 0001 | N44: =IF(G44="","-",CONCATENATE(G44,"-",H44,"-",I44,"-",J44,"-",K44,"-",L44,"-",M44)) -> XVNT-IICM-TNM-XX-M3-D-0001 | O44: Nhóm BIM | P44: 40 | Q44: 300 | R44: 300 | S44: Nhóm BIM | T44: 30 | U44: 300 | V44: 300
...
