Workbook

Sheet Huong_Dan
A1: MÔ HÌNH TÀI CHÍNH CDE CIC — HƯỚNG DẪN
A2: Cloud-First | Tiến độ 9/2026 – giữa 2027 | Doanh thu từ 2027
A4: A. QUY ƯỚC MÀU
A5: Vàng đậm + chữ xanh | B5: Đầu vào CẦN khảo sát lại (có mã)
A6: Vàng nhạt + chữ xanh | B6: Đầu vào có thể chỉnh (giả định)
A7: Chữ xanh lá | B7: Công thức liên kết sheet khác
A8: Chữ đen | B8: Công thức tính trong sheet
A10: B. NGUYÊN TẮC
A11: 1 | B11: Chỉ sửa ô MÀU VÀNG ở Gia_Dinh và các sheet chi tiết (Nhan_Su, Thiet_Bi, CP_Khac, Cloud).
A12: 2 | B12: Mọi sheet khác là công thức — tự cập nhật. Mở Excel tự tính (nếu trống bấm F9).
A13: 3 | B13: Mô hình Cloud-First: KHÔNG mua server (thuê cloud → OPEX). On-Premise: khách tự lo hạ tầng.
A14: 4 | B14: NPV dùng quy ước năm 2026 = năm gốc (t=0).
A16: C. DANH MỤC SHEET
A17: Thuat_Ngu | B17: Chú thích thuật ngữ tiếng Anh & viết tắt
A18: Gia_Dinh | B18: Toàn bộ giả định đầu vào (nơi điền chính)
A19: Nhan_Su | B19: Nhân sự bottom-up: đội phát triển (10) + đội vận hành (12/20/22)
A20: Thiet_Bi | B20: Trang thiết bị văn phòng → CAP-02 (Cloud-First, không mua server)
A21: CP_Khac | B21: Bản quyền/API, Marketing, PM/Pháp lý → CAP-03/04/05
A22: Cloud | B22: Chi phí thuê Cloud trong nước → OPX-02
A23: Doanh_Thu | B23: Doanh thu SaaS + On-Premise (PMU, Sở XD, Doanh nghiệp)
A24: Dau_Tu | B24: Tổng hợp CAPEX 25,1 tỷ (CIC 70% / NATIF 30%)
A25: OPEX | B25: Tổng hợp chi phí vận hành
A26: P_and_L | B26: Báo cáo kết quả & dòng tiền
A27: Dong_Tien | B27: Dòng tiền dự án & CIC
A28: NPV_IRR | B28: NPV, IRR, hoàn vốn
... A31: Dashboard | B31: Bảng tổng hợp chỉ số

Sheet Thuat_Ngu
A1: CHÚ THÍCH THUẬT NGỮ & TỪ VIẾT TẮT
A3: A. TÀI CHÍNH
A4: Viết tắt | B4: Tiếng Anh | C4: Giải thích
A5: NPV | B5: Net Present Value | C5: Giá trị hiện tại thuần (>0 là sinh lời).
A6: IRR | B6: Internal Rate of Return | C6: Tỷ suất sinh lợi nội bộ; so với WACC.
A7: WACC | B7: Weighted Average Cost of Capital | C7: Chi phí vốn bình quân (chiết khấu 12%).
A8: CAPEX | B8: Capital Expenditure | C8: Chi phí đầu tư ban đầu.
A9: OPEX | B9: Operating Expenditure | C9: Chi phí vận hành thường xuyên.
A10: COGS | B10: Cost of Goods Sold | C10: Giá vốn dịch vụ (40% doanh thu).
A11: AMC | B11: Annual Maintenance Contract | C11: Phí bảo trì hàng năm (15% giá HĐ lũy kế).
A12: ARPU | B12: Average Revenue Per User | C12: Doanh thu bình quân/user.
A13: P&L | B13: Profit and Loss | C13: Báo cáo kết quả kinh doanh.
A15: B. KINH DOANH
A16: Viết tắt | B16: Tiếng Anh | C16: Giải thích
A17: SaaS | B17: Software as a Service | C17: Phần mềm thuê bao trên cloud.
A18: On-Premise | C18: Cài đặt tại hạ tầng khách hàng.
A19: B2G / B2B | B19: Business to Government / Business | C19: Bán cho nhà nước / doanh nghiệp.
A20: PMU | B20: Project Management Unit | C20: Ban Quản lý dự án.
A21: MVP | B21: Minimum Viable Product | C21: Sản phẩm khả dụng tối thiểu.
A23: C. CÔNG NGHỆ
A24: Viết tắt | B24: Tiếng Anh | C24: Giải thích
A25: CDE | B25: Common Data Environment | C25: Môi trường dữ liệu chung.
A26: BIM | B26: Building Information Modeling | C26: Mô hình thông tin công trình.
A27: IFC | B27: Industry Foundation Classes | C27: Định dạng mở dữ liệu BIM (ISO 16739).
A28: WebGL | B28: Web Graphics Library | C28: Đồ họa 3D trên trình duyệt.
A29: API | B29: Application Programming Interface | C29: Giao diện kết nối hệ thống.
A30: SDK | B30: Software Development Kit | C30: Bộ công cụ phát triển phần mềm.
A31: CDN | B31: Content Delivery Network | C31: Mạng phân phối nội dung (tăng tốc tải).
A32: CI/CD | B32: Continuous Integration / Deployment | C32: Tích hợp & triển khai liên tục.
A34: D. AN NINH & PHÁP LÝ
A35: Viết tắt | B35: Tiếng Anh | C35: Giải thích
A36: QCVN 12 | C36: Quy chuẩn kỹ thuật quốc gia về an ninh mạng.
A37: NATIF | B37: National Technology Innovation Foundation | C37: Quỹ Đổi mới công nghệ quốc gia.
A38: NĐ 13/2023 | C38: Nghị định về bảo vệ dữ liệu cá nhân.
A39: G&A | B39: General & Administrative | C39: Chi phí quản lý doanh nghiệp.
A40: IP | B40: Intellectual Property | C40: Sở hữu trí tuệ.
A41: BHXH | C41: Bảo hiểm xã hội (21,5% lương).

Sheet Gia_Dinh
A1: GIẢ ĐỊNH ĐẦU VÀO (INPUTS)
A2: Chỉ sửa ô vàng. Mỗi dòng có MÃ để tham chiếu khi khảo sát.
A3: Mã | B3: Khoản mục | C3: Đơn vị | D3: 2026 | E3: 2027 | F3: 2028 | G3: 2029 | H3: 2030 | I3: Ghi chú
A4: A. THAM SỐ TÀI CHÍNH CHUNG
A5: FIN-01 | B5: Giá vốn dịch vụ (COGS) / doanh thu | C5: % | D5: 0.4 | E5: 0.4 | F5: 0.4 | G5: 0.4 | H5: 0.4 | I5: ⚠️ Triển khai local, băng thông, API, đào tạo
A6: FIN-02 | B6: Biên lợi nhuận gộp | C6: % | D6: =1-D5 | E6: =1-D5 | F6: =1-D5 | G6: =1-D5 | H6: =1-D5
A7: FIN-03 | B7: WACC (tỷ lệ chiết khấu) | C7: % | D7: 0.12 | E7: 0.12 | F7: 0.12 | G7: 0.12 | H7: 0.12 | I7: ✅ Benchmark tech VN
A8: FIN-04 | B8: Thuế TNDN | C8: % | D8: 0.1 | E8: 0.1 | F8: 0.1 | G8: 0.1 | H8: 0.1 | I8: ✅ Ưu đãi DN công nghệ
A9: FIN-05 | B9: Tỷ lệ vốn CIC (đối ứng) | C9: % | D9: 0.7 | E9: 0.7 | F9: 0.7 | G9: 0.7 | H9: 0.7 | I9: ✅ Cam kết 70/30
A10: FIN-06 | B10: Tỷ lệ vốn NATIF (tài trợ) | C10: % | D10: =1-D9 | E10: =1-D9 | F10: =1-D9 | G10: =1-D9 | H10: =1-D9
A11: FIN-07 | B11: Hệ số tải nhân sự vận hành (overhead) | C11: x | D11: 0 | E11: 1.62 | F11: 1.49 | G11: 1.46 | H11: 1.46 | I11: BHXH + lương 13 + thưởng + tuyển dụng/phúc lợi
A13: B. DOANH THU SaaS
A14: SAAS-01 | B14: Người dùng active cuối kỳ | C14: user | D14: 0 | E14: 1000 | F14: 4000 | G14: 9000 | H14: 15000 | I14: ❌ Sản phẩm ra mắt 2027
A15: SAAS-02 | B15: ARPU (giá TB/user/tháng) | C15: tr | D15: 0 | E15: 0.5 | F15: 0.5 | G15: 0.52 | H15: 0.55 | I15: ❌ ~6 tr/user/năm
A16: SAAS-03 | B16: Số tháng thương mại trong năm | C16: tháng | D16: 0 | E16: 6 | F16: 12 | G16: 12 | H16: 12 | I16: 2027 từ giữa năm
A18: C. ON-PREMISE — PMU (Ban QLDA)
A19: OPP-01 | B19: Hợp đồng PMU mới trong năm | C19: HĐ | D19: 0 | E19: 2 | F19: 6 | G19: 10 | H19: 12 | I19: ❌ Lũy kế 30 PMU tới 2030
A20: OPP-02 | B20: Giá HĐ PMU (tăng dần) | C20: tỷ | D20: 0 | E20: 2 | F20: 2.3 | G20: 2.6 | H20: 3 | I20: ❌ 2,0 → 3,0 tỷ
A22: D. ON-PREMISE — SỞ XÂY DỰNG
A23: OSX-01 | B23: Hợp đồng Sở XD mới trong năm | C23: HĐ | D23: 0 | E23: 1 | F23: 3 | G23: 5 | H23: 6 | I23: ❌ Lũy kế 15 Sở tới 2030
A24: OSX-02 | B24: Giá HĐ Sở XD (tăng dần) | C24: tỷ | D24: 0 | E24: 1.8 | F24: 2 | G24: 2.2 | H24: 2.5 | I24: ❌ 1,8 → 2,5 tỷ
A26: E. ON-PREMISE — DOANH NGHIỆP LỚN
A27: OPV-01 | B27: Hợp đồng doanh nghiệp mới | C27: HĐ | D27: 0 | E27: 1 | F27: 3 | G27: 4 | H27: 5 | I27: ⚠️ Lũy kế 13 DN tới 2030
A28: OPV-02 | B28: Giá HĐ doanh nghiệp (tăng dần) | C28: tỷ | D28: 0 | E28: 3 | F28: 3.4 | G28: 3.8 | H28: 4.2 | I28: ⚠️ 3,0 → 4,2 tỷ
A29: AMC-01 | B29: Phí bảo trì hàng năm (% giá HĐ lũy kế) | C29: % | D29: 0.15 | E29: 0.15 | F29: 0.15 | G29: 0.15 | H29: 0.15 | I29: Thu từ năm thứ 2
A31: F. ĐẦU TƯ CAPEX (link từ sheet chi tiết)
A32: CAP-01 | B32: Nhân sự phát triển lõi | C32: tỷ | D32: =Nhan_Su!D28 | E32: =Nhan_Su!E28 | F32: =Nhan_Su!F28 | G32: =Nhan_Su!G28 | H32: =Nhan_Su!H28 | I32: ← Nhan_Su (đội 10 người)
A33: CAP-02 | B33: Trang thiết bị văn phòng | C33: tỷ | D33: =Thiet_Bi!D10 | E33: =Thiet_Bi!E10 | F33: =Thiet_Bi!F10 | G33: =Thiet_Bi!G10 | H33: =Thiet_Bi!H10 | I33: ← Thiet_Bi (Cloud-First)
A34: CAP-03 | B34: Bản quyền & API tích hợp | C34: tỷ | D34: =CP_Khac!D8 | E34: =CP_Khac!E8 | F34: =CP_Khac!F8 | G34: =CP_Khac!G8 | H34: =CP_Khac!H8 | I34: ← CP_Khac (nhóm A)
A35: CAP-04 | B35: Marketing & Sales ra mắt | C35: tỷ | D35: =CP_Khac!D15 | E35: =CP_Khac!E15 | F35: =CP_Khac!F15 | G35: =CP_Khac!G15 | H35: =CP_Khac!H15 | I35: ← CP_Khac (nhóm B)
A36: CAP-05 | B36: Tư vấn, PM & Pháp lý | C36: tỷ | D36: =CP_Khac!D21 | E36: =CP_Khac!E21 | F36: =CP_Khac!F21 | G36: =CP_Khac!G21 | H36: =CP_Khac!H21 | I36: ← CP_Khac (nhóm C)
A38: G. CHI PHÍ VẬN HÀNH OPEX
A39: OPX-01 | B39: Nhân sự vận hành | C39: tỷ | D39: =Nhan_Su!D46 | E39: =Nhan_Su!E46 | F39: =Nhan_Su!F46 | G39: =Nhan_Su!G46 | H39: =Nhan_Su!H46 | I39: ← Nhan_Su (đội vận hành)
A40: OPX-02 | B40: Thuê hạ tầng Cloud trong nước | C40: tỷ | D40: =Cloud!D9 | E40: =Cloud!E9 | F40: =Cloud!F9 | G40: =Cloud!G9 | H40: =Cloud!H9 | I40: ← Cloud
A41: OPX-03 | B41: Chi phí vận hành khác | C41: tỷ | D41: 0 | E41: 11 | F41: 22 | G41: 26 | H41: 31 | I41: ⚠️ Văn phòng, marketing thường niên, license API, pentest an ninh

Sheet Nhan_Su
A1: NHÂN SỰ & TIỀN LƯƠNG (BOTTOM-UP)
A2: Đội phát triển (CAPEX) + đội vận hành (OPEX). Sửa ô vàng.
A4: A. THAM SỐ PHỤ PHÍ (đội phát triển)
A5: NS-L01 | B5: BHXH/BHYT/BHTN (% lương) | D5: 0.215
A6: NS-L02 | B6: Văn phòng /người/tháng (tr) | D6: 10
A7: NS-L03 | B7: Thiết bị & công cụ /người/năm (tr) | D7: 8
A8: NS-L04 | B8: Phúc lợi & đào tạo /người/tháng (tr) | D8: 2
A9: NS-L05 | B9: AI tools /người/tháng (tr) | D9: 1.5
A11: B. ĐỘI NGŨ PHÁT TRIỂN (10 người, build 9/2026–giữa 2027 → CAP-01)
A12: Mã | B12: Vị trí | C12: Lương/th (tr) | D12: 2026 | E12: 2027 | F12: 2028 | G12: 2029 | H12: 2030
A13: NS-01 | B13: CTO / Kiến trúc trưởng (gộp Eng Director + Tech Lead) | C13: 78 | D13: 1 | E13: 1 | F13: 0 | G13: 0 | H13: 0
A14: NS-02 | B14: Senior Kỹ sư BIM/IFC + WebGL (lõi đồ họa) | C14: 55 | D14: 3 | E14: 3 | F14: 0 | G14: 0 | H14: 0
A15: NS-03 | B15: AI/ML + Data Engineer | C15: 50 | D15: 1 | E15: 1 | F15: 0 | G15: 0 | H15: 0
A16: NS-04 | B16: Full-stack Backend / DevOps | C16: 42 | D16: 2 | E16: 2 | F16: 0 | G16: 0 | H16: 0
A17: NS-05 | B17: Frontend / UX-UI Engineer | C17: 36 | D17: 1 | E17: 1 | F17: 0 | G17: 0 | H17: 0
A18: NS-06 | B18: Security Engineer (QCVN 12) | C18: 58 | D18: 1 | E18: 1 | F18: 0 | G18: 0 | H18: 0
A19: NS-07 | B19: Product Manager / BIM BA (gộp PM + BA + QA) | C19: 55 | D19: 1 | E19: 1 | F19: 0 | G19: 0 | H19: 0
B20: Số tháng tính lương | D20: 4 | E20: 6 | F20: 0 | G20: 0 | H20: 0
B21: Tổng nhân sự (người) | D21: =SUM(D13:D19) | E21: =SUM(E13:E19) | F21: =SUM(F13:F19) | G21: =SUM(G13:G19) | H21: =SUM(H13:H19)
B22: Lương gộp/năm | D22: =SUMPRODUCT($C$13:$C$19,D13:D19)*D20/1000 | E22: =SUMPRODUCT($C$13:$C$19,E13:E19)*E20/1000 | F22: =SUMPRODUCT($C$13:$C$19,F13:F19)*F20/1000 | G22: =SUMPRODUCT($C$13:$C$19,G13:G19)*G20/1000 | H22: =SUMPRODUCT($C$13:$C$19,H13:H19)*H20/1000 | I22: Σ(SL×lương)×tháng/1000
B23: + BHXH/BHYT/BHTN | D23: =D22*$D$5 | E23: =E22*$D$5 | F23: =F22*$D$5 | G23: =G22*$D$5 | H23: =H22*$D$5
B24: + Văn phòng | D24: =D21*$D$6*D20/1000 | E24: =E21*$D$6*E20/1000 | F24: =F21*$D$6*F20/1000 | G24: =G21*$D$6*G20/1000 | H24: =H21*$D$6*H20/1000
B25: + Thiết bị & công cụ | D25: =D21*$D$7*D20/12/1000 | E25: =E21*$D$7*E20/12/1000 | F25: =F21*$D$7*F20/12/1000 | G25: =G21*$D$7*G20/12/1000 | H25: =H21*$D$7*H20/12/1000
B26: + Phúc lợi & đào tạo | D26: =D21*$D$8*D20/1000 | E26: =E21*$D$8*E20/1000 | F26: =F21*$D$8*F20/1000 | G26: =G21*$D$8*G20/1000 | H26: =H21*$D$8*H20/1000
B27: + AI tools | D27: =D21*$D$9*D20/1000 | E27: =E21*$D$9*E20/1000 | F27: =F21*$D$9*F20/1000 | G27: =G21*$D$9*G20/1000 | H27: =H21*$D$9*H20/1000
B28: ➜ NHÂN SỰ CAPEX (all-in) → CAP-01 | D28: =D22+D23+D24+D25+D26+D27 | E28: =E22+E23+E24+E25+E26+E27 | F28: =F22+F23+F24+F25+F26+F27 | G28: =G22+G23+G24+G25+G26+G27 | H28: =H22+H23+H24+H25+H26+H27 | I28: all-in
A30: C. ĐỘI NGŨ VẬN HÀNH (12→20→22 người, từ giữa 2027 → OPX-01)
A31: Mã | B31: Vị trí | C31: Lương/th (tr) | D31: 2026 | E31: 2027 | F31: 2028 | G31: 2029 | H31: 2030
A32: NS-O1 | B32: Quản lý vận hành | C32: 50 | D32: 0 | E32: 1 | F32: 1 | G32: 1 | H32: 1
A33: NS-O2 | B33: Bảo trì BIM / IFC Support | C33: 40 | D33: 0 | E33: 1 | F33: 2 | G33: 2 | H33: 2
A34: NS-O3 | B34: Kỹ sư Backend / DevOps | C34: 42 | D34: 0 | E34: 1 | F34: 2 | G34: 2 | H34: 2
A35: NS-O4 | B35: Kỹ sư Frontend | C35: 36 | D35: 0 | E35: 1 | F35: 1 | G35: 1 | H35: 1
A36: NS-O5 | B36: Chuyên viên An ninh (Security Ops) | C36: 45 | D36: 0 | E36: 1 | F36: 1 | G36: 1 | H36: 1
A37: NS-O6 | B37: Kỹ sư QA / Kiểm thử | C37: 30 | D37: 0 | E37: 1 | F37: 1 | G37: 1 | H37: 1
A38: NS-O7 | B38: Nhân viên Sales (B2B/B2G) | C38: 25 | D38: 0 | E38: 1 | F38: 3 | G38: 4 | H38: 4
A39: NS-O8 | B39: Chăm sóc KH (Customer Success) | C39: 25 | D39: 0 | E39: 1 | F39: 3 | G39: 4 | H39: 4
A40: NS-O9 | B40: Hỗ trợ kỹ thuật (L1/L2 Support) | C40: 20 | D40: 0 | E40: 2 | F40: 4 | G40: 4 | H40: 4
A41: NS-O10 | B41: Nhân sự G&A (HR, Kế toán, Admin) | C41: 22 | D41: 0 | E41: 2 | F41: 2 | G41: 2 | H41: 2
B42: Số tháng tính lương | D42: 0 | E42: 6 | F42: 12 | G42: 12 | H42: 12
B43: Hệ số tải (← Gia_Dinh FIN-07) | D43: =Gia_Dinh!D11 | E43: =Gia_Dinh!E11 | F43: =Gia_Dinh!F11 | G43: =Gia_Dinh!G11 | H43: =Gia_Dinh!H11
...

Sheet Thiet_Bi
A1: TRANG THIẾT BỊ VĂN PHÒNG (CAP-02)
A2: Cloud-First: KHÔNG mua server (thuê cloud → OPEX). Chỉ thiết bị làm việc.
A4: THIẾT BỊ ĐỘI NGŨ (mua 1 lần)
A5: Mã | B5: Hạng mục | C5: Đơn giá (tr) | D5: SL 2026 | E5: SL 2027 | F5: SL 2028 | G5: SL 2029 | H5: SL 2030 | I5: Ghi chú
A6: TB-01 | B6: Workstation chuyên dụng BIM/WebGL | C6: 50 | D6: 3 | E6: 0 | F6: 0 | G6: 0 | H6: 0 | I6: Đội đồ họa 3D
A7: TB-02 | B7: Laptop cấu hình cao cho Dev | C7: 35 | D7: 7 | E7: 1 | F7: 0 | G7: 0 | H7: 0 | I7: Đội phát triển
A8: TB-03 | B8: Thiết bị mạng & tường lửa văn phòng | C8: 200 | D8: 1 | E8: 0 | F8: 0 | G8: 0 | H8: 0 | I8: An ninh local
A9: TB-04 | B9: Setup hạ tầng văn phòng & bổ sung | C9: 105 | D9: 1 | E9: 3 | F9: 0 | G9: 0 | H9: 0 | I9: Bàn ghế, màn hình, mở rộng 2027
B10: TỔNG THIẾT BỊ → CAP-02 | D10: =SUMPRODUCT($C$6:$C$9,D6:D9)/1000 | E10: =SUMPRODUCT($C$6:$C$9,E6:E9)/1000 | F10: =SUMPRODUCT($C$6:$C$9,F6:F9)/1000 | G10: =SUMPRODUCT($C$6:$C$9,G6:G9)/1000 | H10: =SUMPRODUCT($C$6:$C$9,H6:H9)/1000

Sheet CP_Khac
A1: BẢN QUYỀN, MARKETING & TƯ VẤN (BOTTOM-UP)
A2: Tổng từng nhóm → CAP-03/04/05. (đơn giá: triệu VNĐ)
A4: A. BẢN QUYỀN & API TÍCH HỢP (→ CAP-03)
A5: Mã | B5: Hạng mục | C5: Đơn giá (tr) | D5: SL 2026 | E5: SL 2027 | F5: SL 2028 | G5: SL 2029 | H5: SL 2030 | I5: Ghi chú
A6: BQ-01 | B6: Bản quyền SDK BIM/IFC thương mại (/năm) | C6: 2000 | D6: 1 | E6: 1 | F6: 0 | G6: 0 | H6: 0 | I6: ODA SDK, xử lý IFC
A7: BQ-02 | B7: Engine WebGL tối ưu hiển thị 3D (/năm) | C7: 1000 | D7: 1 | E7: 1 | F7: 0 | G7: 0 | H7: 0 | I7: Render 3D nặng
B8: TỔNG NHÓM | D8: =SUMPRODUCT($C$6:$C$7,D6:D7)/1000 | E8: =SUMPRODUCT($C$6:$C$7,E6:E7)/1000 | F8: =SUMPRODUCT($C$6:$C$7,F6:F7)/1000 | G8: =SUMPRODUCT($C$6:$C$7,G6:G7)/1000 | H8: =SUMPRODUCT($C$6:$C$7,H6:H7)/1000
A10: B. MARKETING & SALES RA MẮT (→ CAP-04)
A11: Mã | B11: Hạng mục | C11: Đơn giá (tr) | D11: SL 2026 | E11: SL 2027 | F11: SL 2028 | G11: SL 2029 | H11: SL 2030 | I11: Ghi chú
A12: MK-01 | B12: Nghiên cứu thị trường xây dựng 2026 | C12: 900 | D12: 1 | E12: 0 | F12: 0 | G12: 0 | H12: 0 | I12: Khảo sát thị trường
A13: MK-02 | B13: Hội thảo PMU/Sở XD (/sự kiện) | C13: 500 | D13: 0 | E13: 6 | F13: 0 | G13: 0 | H13: 0 | I13: Giới thiệu giải pháp 2027
A14: MK-03 | B14: Chiến dịch marketing B2B trực tiếp | C14: 1500 | D14: 0 | E14: 1 | F14: 0 | G14: 0 | H14: 0 | I14: Ra mắt 2027
B15: TỔNG NHÓM | D15: =SUMPRODUCT($C$12:$C$14,D12:D14)/1000 | E15: =SUMPRODUCT($C$12:$C$14,E12:E14)/1000 | F15: =SUMPRODUCT($C$12:$C$14,F12:F14)/1000 | G15: =SUMPRODUCT($C$12:$C$14,G12:G14)/1000 | H15: =SUMPRODUCT($C$12:$C$14,H12:H14)/1000
A17: C. TƯ VẤN, PM & PHÁP LÝ (→ CAP-05)
A18: Mã | B18: Hạng mục | C18: Đơn giá (tr) | D18: SL 2026 | E18: SL 2027 | F18: SL 2028 | G18: SL 2029 | H18: SL 2030 | I18: Ghi chú
A19: PM-01 | B19: Tư vấn kỹ thuật & kiểm định QCVN 12 | C19: 1000 | D19: 1 | E19: 3 | F19: 0 | G19: 0 | H19: 0 | I19: Cao điểm kiểm định an ninh 2027
A20: PM-02 | B20: Đăng ký IP, pháp lý sản phẩm | C20: 800 | D20: 1 | E20: 0 | F20: 0 | G20: 0 | H20: 0 | I20: Sở hữu trí tuệ (2026)
B21: TỔNG NHÓM | D21: =SUMPRODUCT($C$19:$C$20,D19:D20)/1000 | E21: =SUMPRODUCT($C$19:$C$20,E19:E20)/1000 | F21: =SUMPRODUCT($C$19:$C$20,F19:F20)/1000 | G21: =SUMPRODUCT($C$19:$C$20,G19:G20)/1000 | H21: =SUMPRODUCT($C$19:$C$20,H19:H20)/1000

Sheet Cloud
A1: CHI PHÍ THUÊ CLOUD TRONG NƯỚC (OPX-02)
A2: Viettel/VNPT/CMC Cloud. Tăng theo số user & dung lượng BIM.
A3: Mã | B3: Khoản mục | C3: Đơn vị | D3: 2026 | E3: 2027 | F3: 2028 | G3: 2029 | H3: 2030 | I3: Khảo sát / Giải trình
A4: HẠNG MỤC THUÊ CLOUD
A5: CL-01 | B5: Server lưu trữ BIM & Data | C5: tỷ | D5: 0.05 | E5: 0.4 | F5: 1 | G5: 1.8 | H5: 2.5 | I5: Object Storage ~900đ/GB/th, tích lũy tăng
A6: CL-02 | B6: Server xử lý WebGL & Node | C6: tỷ | D6: 0.05 | E6: 0.4 | F6: 0.8 | G6: 1.2 | H6: 1.6 | I6: VM 16vCPU/64GB render server-side
A7: CL-03 | B7: Dịch vụ DevOps & Monitor | C7: tỷ | D7: 0.05 | E7: 0.2 | F7: 0.3 | G7: 0.4 | H7: 0.6 | I7: Load Balancer, Firewall, CI/CD
A8: CL-04 | B8: Bản quyền OS, DB & SSL | C8: tỷ | D8: 0.05 | E8: 0.2 | F8: 0.4 | G8: 0.6 | H8: 0.8 | I8: PostgreSQL Enterprise, SSL
B9: TỔNG OPEX THUÊ CLOUD → OPX-02 | C9: tỷ | D9: =SUM(D5:D8) | E9: =SUM(E5:E8) | F9: =SUM(F5:F8) | G9: =SUM(G5:G8) | H9: =SUM(H5:H8)

Sheet Doanh_Thu
A1: DỰ PHÓNG DOANH THU 5 NĂM
A2: SaaS + On-Premise (PMU, Sở XD, Doanh nghiệp). Đơn vị: tỷ VNĐ.
A3: Mã | B3: Khoản mục | C3: Đơn vị | D3: 2026 | E3: 2027 | F3: 2028 | G3: 2029 | H3: 2030 | I3: Diễn giải
A4: KÊNH 1 — SaaS
B5: User active cuối kỳ | C5: user | D5: =Gia_Dinh!D14 | E5: =Gia_Dinh!E14 | F5: =Gia_Dinh!F14 | G5: =Gia_Dinh!G14 | H5: =Gia_Dinh!H14
B6: ARPU (tr/user/tháng) | C6: tr | D6: =Gia_Dinh!D15 | E6: =Gia_Dinh!E15 | F6: =Gia_Dinh!F15 | G6: =Gia_Dinh!G15 | H6: =Gia_Dinh!H15
B7: Số tháng thương mại | C7: tháng | D7: =Gia_Dinh!D16 | E7: =Gia_Dinh!E16 | F7: =Gia_Dinh!F16 | G7: =Gia_Dinh!G16 | H7: =Gia_Dinh!H16
B8: Doanh thu SaaS | C8: tỷ | D8: =D5*D6*D7/1000 | E8: =E5*E6*E7/1000 | F8: =F5*F6*F7/1000 | G8: =G5*G6*G7/1000 | H8: =H5*H6*H7/1000 | I8: user×ARPU×tháng/1000
A10: KÊNH 2 — ON-PREMISE PMU
B11: PMU — hợp đồng mới | C11: HĐ | D11: =Gia_Dinh!D19 | E11: =Gia_Dinh!E19 | F11: =Gia_Dinh!F19 | G11: =Gia_Dinh!G19 | H11: =Gia_Dinh!H19
B12: PMU — giá HĐ | C12: tỷ | D12: =Gia_Dinh!D20 | E12: =Gia_Dinh!E20 | F12: =Gia_Dinh!F20 | G12: =Gia_Dinh!G20 | H12: =Gia_Dinh!H20
B13: PMU — license mới | C13: tỷ | D13: =D11*D12 | E13: =E11*E12 | F13: =F11*F12 | G13: =G11*G12 | H13: =H11*H12
B14: PMU — license lũy kế | C14: tỷ | D14: =D13 | E14: =D14+E13 | F14: =E14+F13 | G14: =F14+G13 | H14: =G14+H13
B15: PMU — bảo trì (AMC) | C15: tỷ | D15: 0 | E15: =D14*Gia_Dinh!E29 | F15: =E14*Gia_Dinh!F29 | G15: =F14*Gia_Dinh!G29 | H15: =G14*Gia_Dinh!H29
B16: PMU — TỔNG | C16: tỷ | D16: =D13+D15 | E16: =E13+E15 | F16: =F13+F15 | G16: =G13+G15 | H16: =H13+H15
A18: KÊNH 3 — ON-PREMISE SỞ XÂY DỰNG
B19: Sở XD — hợp đồng mới | C19: HĐ | D19: =Gia_Dinh!D23 | E19: =Gia_Dinh!E23 | F19: =Gia_Dinh!F23 | G19: =Gia_Dinh!G23 | H19: =Gia_Dinh!H23
B20: Sở XD — giá HĐ | C20: tỷ | D20: =Gia_Dinh!D24 | E20: =Gia_Dinh!E24 | F20: =Gia_Dinh!F24 | G20: =Gia_Dinh!G24 | H20: =Gia_Dinh!H24
B21: Sở XD — license mới | C21: tỷ | D21: =D19*D20 | E21: =E19*E20 | F21: =F19*F20 | G21: =G19*G20 | H21: =H19*H20
B22: Sở XD — license lũy kế | C22: tỷ | D22: =D21 | E22: =D22+E21 | F22: =E22+F21 | G22: =F22+G21 | H22: =G22+H21
B23: Sở XD — bảo trì (AMC) | C23: tỷ | D23: 0 | E23: =D22*Gia_Dinh!E29 | F23: =E22*Gia_Dinh!F29 | G23: =F22*Gia_Dinh!G29 | H23: =G22*Gia_Dinh!H29
B24: Sở XD — TỔNG | C24: tỷ | D24: =D21+D23 | E24: =E21+E23 | F24: =F21+F23 | G24: =G21+G23 | H24: =H21+H23
A26: KÊNH 4 — ON-PREMISE DOANH NGHIỆP
B27: Doanh nghiệp — hợp đồng mới | C27: HĐ | D27: =Gia_Dinh!D27 | E27: =Gia_Dinh!E27 | F27: =Gia_Dinh!F27 | G27: =Gia_Dinh!G27 | H27: =Gia_Dinh!H27
B28: Doanh nghiệp — giá HĐ | C28: tỷ | D28: =Gia_Dinh!D28 | E28: =Gia_Dinh!E28 | F28: =Gia_Dinh!F28 | G28: =Gia_Dinh!G28 | H28: =Gia_Dinh!H28
B29: Doanh nghiệp — license mới | C29: tỷ | D29: =D27*D28 | E29: =E27*E28 | F29: =F27*F28 | G29: =G27*G28 | H29: =H27*H28
B30: Doanh nghiệp — license lũy kế | C30: tỷ | D30: =D29 | E30: =D30+E29 | F30: =E30+F29 | G30: =F30+G29 | H30: =G30+H29
B31: Doanh nghiệp — bảo trì (AMC) | C31: tỷ | D31: 0 | E31: =D30*Gia_Dinh!E29 | F31: =E30*Gia_Dinh!F29 | G31: =F30*Gia_Dinh!G29 | H31: =G30*Gia_Dinh!H29
B32: Doanh nghiệp — TỔNG | C32: tỷ | D32: =D29+D31 | E32: =E29+E31 | F32: =F29+F31 | G32: =G29+G31 | H32: =H29+H31
A34: TỔNG HỢP
B35: TỔNG DOANH THU | C35: tỷ | D35: =D8+D16+D24+D32 | E35: =E8+E16+E24+E32 | F35: =F8+F16+F24+F32 | G35: =G8+G16+G24+G32 | H35: =H8+H16+H24+H32

Sheet Dau_Tu
A1: TỔNG HỢP VỐN ĐẦU TƯ — CAPEX
A2: Cloud-First, CIC 70% + NATIF 30%. Đơn vị: tỷ VNĐ.
A3: Mã | B3: Khoản mục | C3: Đơn vị | D3: 2026 | E3: 2027 | F3: 2028 | G3: 2029 | H3: 2030 | I3: Nguồn
A4: HẠNG MỤC CAPEX (link Gia_Dinh)
A5: CAP-01 | B5: Nhân sự phát triển lõi | C5: tỷ | D5: =Gia_Dinh!D32 | E5: =Gia_Dinh!E32 | F5: =Gia_Dinh!F32 | G5: =Gia_Dinh!G32 | H5: =Gia_Dinh!H32
A6: CAP-02 | B6: Trang thiết bị văn phòng | C6: tỷ | D6: =Gia_Dinh!D33 | E6: =Gia_Dinh!E33 | F6: =Gia_Dinh!F33 | G6: =Gia_Dinh!G33 | H6: =Gia_Dinh!H33
A7: CAP-03 | B7: Bản quyền & API tích hợp | C7: tỷ | D7: =Gia_Dinh!D34 | E7: =Gia_Dinh!E34 | F7: =Gia_Dinh!F34 | G7: =Gia_Dinh!G34 | H7: =Gia_Dinh!H34
A8: CAP-04 | B8: Marketing & Sales ra mắt | C8: tỷ | D8: =Gia_Dinh!D35 | E8: =Gia_Dinh!E35 | F8: =Gia_Dinh!F35 | G8: =Gia_Dinh!G35 | H8: =Gia_Dinh!H35
A9: CAP-05 | B9: Tư vấn, PM & Pháp lý | C9: tỷ | D9: =Gia_Dinh!D36 | E9: =Gia_Dinh!E36 | F9: =Gia_Dinh!F36 | G9: =Gia_Dinh!G36 | H9: =Gia_Dinh!H36
B10: TỔNG CAPEX/năm | C10: tỷ | D10: =SUM(D5:D9) | E10: =SUM(E5:E9) | F10: =SUM(F5:F9) | G10: =SUM(G5:G9) | H10: =SUM(H5:H9) | I10: =SUM(D10:H10)
B11: Vốn CIC (70%) | C11: tỷ | D11: =D10*Gia_Dinh!D9 | E11: =E10*Gia_Dinh!E9 | F11: =F10*Gia_Dinh!F9 | G11: =G10*Gia_Dinh!G9 | H11: =H10*Gia_Dinh!H9 | I11: =SUM(D11:H11)
B12: Vốn NATIF (30%) | C12: tỷ | D12: =D10*Gia_Dinh!D10 | E12: =E10*Gia_Dinh!E10 | F12: =F10*Gia_Dinh!F10 | G12: =G10*Gia_Dinh!G10 | H12: =H10*Gia_Dinh!H10 | I12: =SUM(D12:H12)

Sheet OPEX
A1: TỔNG HỢP CHI PHÍ VẬN HÀNH — OPEX
A2: Đơn vị: tỷ VNĐ.
A3: Mã | B3: Khoản mục | C3: Đơn vị | D3: 2026 | E3: 2027 | F3: 2028 | G3: 2029 | H3: 2030 | I3: Nguồn
A4: HẠNG MỤC OPEX
A5: OPX-01 | B5: Nhân sự vận hành | C5: tỷ | D5: =Gia_Dinh!D39 | E5: =Gia_Dinh!E39 | F5: =Gia_Dinh!F39 | G5: =Gia_Dinh!G39 | H5: =Gia_Dinh!H39
A6: OPX-02 | B6: Thuê hạ tầng Cloud | C6: tỷ | D6: =Gia_Dinh!D40 | E6: =Gia_Dinh!E40 | F6: =Gia_Dinh!F40 | G6: =Gia_Dinh!G40 | H6: =Gia_Dinh!H40
A7: OPX-03 | B7: Chi phí vận hành khác | C7: tỷ | D7: =Gia_Dinh!D41 | E7: =Gia_Dinh!E41 | F7: =Gia_Dinh!F41 | G7: =Gia_Dinh!G41 | H7: =Gia_Dinh!H41
B8: TỔNG OPEX/năm | C8: tỷ | D8: =SUM(D5:D7) | E8: =SUM(E5:E7) | F8: =SUM(F5:F7) | G8: =SUM(G5:G7) | H8: =SUM(H5:H7)

Sheet P_and_L
A1: BÁO CÁO KẾT QUẢ & DÒNG TIỀN (P&L)
A2: Đơn vị: tỷ VNĐ. Tất cả là công thức.
A3: Mã | B3: Khoản mục | C3: Đơn vị | D3: 2026 | E3: 2027 | F3: 2028 | G3: 2029 | H3: 2030 | I3: Công thức
A4: KẾT QUẢ KINH DOANH
B5: Doanh thu | C5: tỷ | D5: =Doanh_Thu!D35 | E5: =Doanh_Thu!E35 | F5: =Doanh_Thu!F35 | G5: =Doanh_Thu!G35 | H5: =Doanh_Thu!H35 | I5: ← Doanh_Thu
B6: Lợi nhuận gộp (biên 60%) | C6: tỷ | D6: =D5*Gia_Dinh!D6 | E6: =E5*Gia_Dinh!E6 | F6: =F5*Gia_Dinh!F6 | G6: =G5*Gia_Dinh!G6 | H6: =H5*Gia_Dinh!H6
B7: Chi phí đầu tư (CAPEX) | C7: tỷ | D7: =-Dau_Tu!D10 | E7: =-Dau_Tu!E10 | F7: =-Dau_Tu!F10 | G7: =-Dau_Tu!G10 | H7: =-Dau_Tu!H10
B8: Chi phí vận hành (OPEX) | C8: tỷ | D8: =-OPEX!D8 | E8: =-OPEX!E8 | F8: =-OPEX!F8 | G8: =-OPEX!G8 | H8: =-OPEX!H8
B9: DÒNG TIỀN RÒNG DỰ ÁN | C9: tỷ | D9: =D6+D7+D8 | E9: =E6+E7+E8 | F9: =F6+F7+F8 | G9: =G6+G7+G8 | H9: =H6+H7+H8 | I9: LN gộp – CAPEX – OPEX
B10: Lũy kế dự án | C10: tỷ | D10: =D9 | E10: =D10+E9 | F10: =E10+F9 | G10: =F10+G9 | H10: =G10+H9

Sheet Dong_Tien
A1: DÒNG TIỀN DỰ ÁN & CIC
A2: Đơn vị: tỷ VNĐ.
A3: Mã | B3: Khoản mục | C3: Đơn vị | D3: 2026 | E3: 2027 | F3: 2028 | G3: 2029 | H3: 2030 | I3: Ghi chú
A4: GÓC ĐỘ TOÀN DỰ ÁN
B5: Dòng tiền ròng dự án | C5: tỷ | D5: =P_and_L!D9 | E5: =P_and_L!E9 | F5: =P_and_L!F9 | G5: =P_and_L!G9 | H5: =P_and_L!H9
B6: Lũy kế dự án | C6: tỷ | D6: =P_and_L!D10 | E6: =P_and_L!E10 | F6: =P_and_L!F10 | G6: =P_and_L!G10 | H6: =P_and_L!H10
A8: GÓC ĐỘ CIC (vốn đối ứng 70%)
B9: Dòng tiền ròng CIC | C9: tỷ | D9: =P_and_L!D6-Dau_Tu!D11+P_and_L!D8 | E9: =P_and_L!E6-Dau_Tu!E11+P_and_L!E8 | F9: =P_and_L!F6-Dau_Tu!F11+P_and_L!F8 | G9: =P_and_L!G6-Dau_Tu!G11+P_and_L!G8 | H9: =P_and_L!H6-Dau_Tu!H11+P_and_L!H8 | I9: LN gộp – vốn CIC – OPEX
B10: Lũy kế CIC | C10: tỷ | D10: =D9 | E10: =D10+E9 | F10: =E10+F9 | G10: =F10+G9 | H10: =G10+H9

Sheet NPV_IRR
A1: ĐÁNH GIÁ HIỆU QUẢ ĐẦU TƯ (NPV / IRR / PAYBACK)
A2: Quy ước: 2026 = năm gốc (t=0). WACC ← Gia_Dinh.
A3: Mã | B3: Khoản mục | C3: Đơn vị | D3: 2026 | E3: 2027 | F3: 2028 | G3: 2029 | H3: 2030 | I3: Giá trị
A4: DÒNG TIỀN
B5: Dòng tiền ròng dự án | C5: tỷ | D5: =Dong_Tien!D5 | E5: =Dong_Tien!E5 | F5: =Dong_Tien!F5 | G5: =Dong_Tien!G5 | H5: =Dong_Tien!H5
B6: Dòng tiền ròng CIC | C6: tỷ | D6: =Dong_Tien!D9 | E6: =Dong_Tien!E9 | F6: =Dong_Tien!F9 | G6: =Dong_Tien!G9 | H6: =Dong_Tien!H9
A8: CHỈ SỐ HIỆU QUẢ (WACC, 2026=t0)
B9: NPV toàn dự án (5 năm) | D9: =D5+NPV(Gia_Dinh!D7,E5:H5)
B10: IRR toàn dự án | D10: =IFERROR(IRR(D5:H5,0.2),"n/a")
B11: NPV đầu tư CIC (5 năm) | D11: =D6+NPV(Gia_Dinh!D7,E6:H6)
B12: IRR đầu tư CIC | D12: =IFERROR(IRR(D6:H6,0.2),"n/a")
B13: Hoàn vốn dự án (năm thứ) | D13: =IF(COUNTIF(Dong_Tien!D6:H6,"<0")=0,0,IF(COUNTIF(Dong_Tien!D6:H6,"<0")>=5,"Sau 5 năm",COUNTIF(Dong_Tien!D6:H6,"<0")-1+(-INDEX(Dong_Tien!D6:H6,COUNTIF(Dong_Tien!D6:H6,"<0")))/INDEX(Dong_Tien!D5:H5,COUNTIF(Dong_Tien!D6:H6,"<0")+1))) | I13: Số năm kể từ đầu 2026 (≈)
B14: Hoàn vốn CIC (năm thứ) | D14: =IF(COUNTIF(Dong_Tien!D10:H10,"<0")=0,0,IF(COUNTIF(Dong_Tien!D10:H10,"<0")>=5,"Sau 5 năm",COUNTIF(Dong_Tien!D10:H10,"<0")-1+(-INDEX(Dong_Tien!D10:H10,COUNTIF(Dong_Tien!D10:H10,"<0")))/INDEX(Dong_Tien!D9:H9,COUNTIF(Dong_Tien!D10:H10,"<0")+1))) | I14: Số năm kể từ đầu 2026 (≈)

Sheet Hoa_Von
A1: PHÂN TÍCH ĐIỂM HÒA VỐN VẬN HÀNH
A2: Trạng thái vận hành đầy đủ (2030).
A4: HÒA VỐN THEO DOANH THU (2030)
B5: Chi phí cố định/năm (OPEX 2030) | D5: =OPEX!H8 | I5: ← OPEX 2030
B6: Biên lợi nhuận gộp | D6: =Gia_Dinh!D6
B7: Doanh thu hòa vốn/năm | D7: =D5/D6 | I7: =chi phí cố định / biên LN gộp
B8: Doanh thu thực tế 2030 | D8: =Doanh_Thu!H35 | I8: Vượt xa ngưỡng hòa vốn

Sheet Do_Nhay
A1: PHÂN TÍCH ĐỘ NHẠY — 3 KỊCH BẢN
A2: Sửa hệ số (ô vàng) để xem tác động NPV dự án.
A4: A. HỆ SỐ KỊCH BẢN (ô vàng)
B5: Kịch bản | C5: Hệ số doanh thu | D5: Hệ số OPEX
B6: Bi quan | C6: 0.7 | D6: 1.15
B7: Cơ sở | C7: 1 | D7: 1
B8: Lạc quan | C8: 1.25 | D8: 0.95
A10: B. NPV DỰ ÁN THEO KỊCH BẢN (2026=t0)
B11: Kịch bản | D11: 2026 | E11: 2027 | F11: 2028 | G11: 2029 | H11: 2030 | I11: NPV dự án
B12: Bi quan | D12: =Doanh_Thu!D35*$C$6*Gia_Dinh!D6-Dau_Tu!D10-OPEX!D8*$D$6 | E12: =Doanh_Thu!E35*$C$6*Gia_Dinh!D6-Dau_Tu!E10-OPEX!E8*$D$6 | F12: =Doanh_Thu!F35*$C$6*Gia_Dinh!D6-Dau_Tu!F10-OPEX!F8*$D$6 | G12: =Doanh_Thu!G35*$C$6*Gia_Dinh!D6-Dau_Tu!G10-OPEX!G8*$D$6 | H12: =Doanh_Thu!H35*$C$6*Gia_Dinh!D6-Dau_Tu!H10-OPEX!H8*$D$6 | I12: =D12+NPV(Gia_Dinh!D7,E12:H12)
B13: Cơ sở | D13: =Doanh_Thu!D35*$C$7*Gia_Dinh!D6-Dau_Tu!D10-OPEX!D8*$D$7 | E13: =Doanh_Thu!E35*$C$7*Gia_Dinh!D6-Dau_Tu!E10-OPEX!E8*$D$7 | F13: =Doanh_Thu!F35*$C$7*Gia_Dinh!D6-Dau_Tu!F10-OPEX!F8*$D$7 | G13: =Doanh_Thu!G35*$C$7*Gia_Dinh!D6-Dau_Tu!G10-OPEX!G8*$D$7 | H13: =Doanh_Thu!H35*$C$7*Gia_Dinh!D6-Dau_Tu!H10-OPEX!H8*$D$7 | I13: =D13+NPV(Gia_Dinh!D7,E13:H13)
B14: Lạc quan | D14: =Doanh_Thu!D35*$C$8*Gia_Dinh!D6-Dau_Tu!D10-OPEX!D8*$D$8 | E14: =Doanh_Thu!E35*$C$8*Gia_Dinh!D6-Dau_Tu!E10-OPEX!E8*$D$8 | F14: =Doanh_Thu!F35*$C$8*Gia_Dinh!D6-Dau_Tu!F10-OPEX!F8*$D$8 | G14: =Doanh_Thu!G35*$C$8*Gia_Dinh!D6-Dau_Tu!G10-OPEX!G8*$D$8 | H14: =Doanh_Thu!H35*$C$8*Gia_Dinh!D6-Dau_Tu!H10-OPEX!H8*$D$8 | I14: =D14+NPV(Gia_Dinh!D7,E14:H14)

Sheet Dashboard
A1: BẢNG TỔNG HỢP CHỈ SỐ (DASHBOARD)
A2: Tự động liên kết từ các sheet.
A4: A. CHỈ SỐ DỰ ÁN
B5: Tổng vốn đầu tư CAPEX (tỷ) | D5: =Dau_Tu!I10
B6: Vốn CIC đối ứng 70% (tỷ) | D6: =Dau_Tu!I11
B7: Tài trợ NATIF 30% (tỷ) | D7: =Dau_Tu!I12
B8: NPV toàn dự án 5 năm (tỷ) | D8: =NPV_IRR!D5+NPV(Gia_Dinh!D7,NPV_IRR!E5:H5)
B9: IRR toàn dự án | D9: =IFERROR(IRR(NPV_IRR!D5:H5,0.2),"n/a")
B10: NPV đầu tư CIC (tỷ) | D10: =NPV_IRR!D6+NPV(Gia_Dinh!D7,NPV_IRR!E6:H6)
B11: IRR đầu tư CIC | D11: =IFERROR(IRR(NPV_IRR!D6:H6,0.2),"n/a")
A13: B. DOANH THU & DÒNG TIỀN THEO NĂM (tỷ)
D14: 2026 | E14: 2027 | F14: 2028 | G14: 2029 | H14: 2030
B15: Doanh thu | D15: =Doanh_Thu!D35 | E15: =Doanh_Thu!E35 | F15: =Doanh_Thu!F35 | G15: =Doanh_Thu!G35 | H15: =Doanh_Thu!H35
B16: Dòng tiền ròng dự án | D16: =P_and_L!D9 | E16: =P_and_L!E9 | F16: =P_and_L!F9 | G16: =P_and_L!G9 | H16: =P_and_L!H9
B17: Lũy kế dự án | D17: =P_and_L!D10 | E17: =P_and_L!E10 | F17: =P_and_L!F10 | G17: =P_and_L!G10 | H17: =P_and_L!H10
B18: Lũy kế CIC | D18: =Dong_Tien!D10 | E18: =Dong_Tien!E10 | F18: =Dong_Tien!F10 | G18: =Dong_Tien!G10 | H18: =Dong_Tien!H10
